[2025-05-11 06:10:51,946: INFO: main: Welcome to our custom log]
[2025-05-11 21:27:09,142: INFO: common: yaml file: config/config.yaml loaded successfully]
[2025-05-11 21:27:09,145: INFO: common: yaml file: params.yaml loaded successfully]
[2025-05-11 21:32:32,575: INFO: common: yaml file: config/config.yaml loaded successfully]
[2025-05-11 21:32:32,575: INFO: common: yaml file: params.yaml loaded successfully]
[2025-05-11 22:04:54,599: INFO: main: >>>>>> stage Data Ingestion stage started <<<<<<]
[2025-05-11 22:04:54,600: INFO: common: yaml file: config/config.yaml loaded successfully]
[2025-05-11 22:04:54,600: INFO: common: yaml file: params.yaml loaded successfully]
[2025-05-11 22:04:54,601: INFO: common: created directory at: artifacts]
[2025-05-11 22:04:54,601: INFO: common: created directory at: artifacts/data_ingestion]
[2025-05-11 22:04:54,601: INFO: data_ingestion: Downloading data from https://drive.google.com/file/d/1C9K6JMeGAbG7jmY8ag1YRMbrHW8q0vQg/view?usp=sharing into file artifacts/data_ingestion/data.zip]
[2025-05-11 22:07:07,936: ERROR: main: HTTPSConnectionPool(host='drive.google.com', port=443): Max retries exceeded with url: /uc?/export=download&id=1C9K6JMeGAbG7jmY8ag1YRMbrHW8q0vQg (Caused by NewConnectionError('<urllib3.connection.HTTPSConnection object at 0x7cdd3fc53b00>: Failed to establish a new connection: [Errno 101] Network is unreachable'))]
Traceback (most recent call last):
  File "/media/liganium/Data/Complete End to End Deep Learning Project With MLFLOW,DVC And Deployment/Kidney-Disease-MLOps-Project/kidney_env/lib/python3.12/site-packages/urllib3/connection.py", line 198, in _new_conn
    sock = connection.create_connection(
           ^^^^^^^^^^^^^^^^^^^^^^^^^^^^^
  File "/media/liganium/Data/Complete End to End Deep Learning Project With MLFLOW,DVC And Deployment/Kidney-Disease-MLOps-Project/kidney_env/lib/python3.12/site-packages/urllib3/util/connection.py", line 85, in create_connection
    raise err
  File "/media/liganium/Data/Complete End to End Deep Learning Project With MLFLOW,DVC And Deployment/Kidney-Disease-MLOps-Project/kidney_env/lib/python3.12/site-packages/urllib3/util/connection.py", line 73, in create_connection
    sock.connect(sa)
OSError: [Errno 101] Network is unreachable

The above exception was the direct cause of the following exception:

Traceback (most recent call last):
  File "/media/liganium/Data/Complete End to End Deep Learning Project With MLFLOW,DVC And Deployment/Kidney-Disease-MLOps-Project/kidney_env/lib/python3.12/site-packages/urllib3/connectionpool.py", line 787, in urlopen
    response = self._make_request(
               ^^^^^^^^^^^^^^^^^^^
  File "/media/liganium/Data/Complete End to End Deep Learning Project With MLFLOW,DVC And Deployment/Kidney-Disease-MLOps-Project/kidney_env/lib/python3.12/site-packages/urllib3/connectionpool.py", line 488, in _make_request
    raise new_e
  File "/media/liganium/Data/Complete End to End Deep Learning Project With MLFLOW,DVC And Deployment/Kidney-Disease-MLOps-Project/kidney_env/lib/python3.12/site-packages/urllib3/connectionpool.py", line 464, in _make_request
    self._validate_conn(conn)
  File "/media/liganium/Data/Complete End to End Deep Learning Project With MLFLOW,DVC And Deployment/Kidney-Disease-MLOps-Project/kidney_env/lib/python3.12/site-packages/urllib3/connectionpool.py", line 1093, in _validate_conn
    conn.connect()
  File "/media/liganium/Data/Complete End to End Deep Learning Project With MLFLOW,DVC And Deployment/Kidney-Disease-MLOps-Project/kidney_env/lib/python3.12/site-packages/urllib3/connection.py", line 704, in connect
    self.sock = sock = self._new_conn()
                       ^^^^^^^^^^^^^^^^
  File "/media/liganium/Data/Complete End to End Deep Learning Project With MLFLOW,DVC And Deployment/Kidney-Disease-MLOps-Project/kidney_env/lib/python3.12/site-packages/urllib3/connection.py", line 213, in _new_conn
    raise NewConnectionError(
urllib3.exceptions.NewConnectionError: <urllib3.connection.HTTPSConnection object at 0x7cdd3fc53b00>: Failed to establish a new connection: [Errno 101] Network is unreachable

The above exception was the direct cause of the following exception:

Traceback (most recent call last):
  File "/media/liganium/Data/Complete End to End Deep Learning Project With MLFLOW,DVC And Deployment/Kidney-Disease-MLOps-Project/kidney_env/lib/python3.12/site-packages/requests/adapters.py", line 667, in send
    resp = conn.urlopen(
           ^^^^^^^^^^^^^
  File "/media/liganium/Data/Complete End to End Deep Learning Project With MLFLOW,DVC And Deployment/Kidney-Disease-MLOps-Project/kidney_env/lib/python3.12/site-packages/urllib3/connectionpool.py", line 841, in urlopen
    retries = retries.increment(
              ^^^^^^^^^^^^^^^^^^
  File "/media/liganium/Data/Complete End to End Deep Learning Project With MLFLOW,DVC And Deployment/Kidney-Disease-MLOps-Project/kidney_env/lib/python3.12/site-packages/urllib3/util/retry.py", line 519, in increment
    raise MaxRetryError(_pool, url, reason) from reason  # type: ignore[arg-type]
    ^^^^^^^^^^^^^^^^^^^^^^^^^^^^^^^^^^^^^^^^^^^^^^^^^^^
urllib3.exceptions.MaxRetryError: HTTPSConnectionPool(host='drive.google.com', port=443): Max retries exceeded with url: /uc?/export=download&id=1C9K6JMeGAbG7jmY8ag1YRMbrHW8q0vQg (Caused by NewConnectionError('<urllib3.connection.HTTPSConnection object at 0x7cdd3fc53b00>: Failed to establish a new connection: [Errno 101] Network is unreachable'))

During handling of the above exception, another exception occurred:

Traceback (most recent call last):
  File "/media/liganium/Data/Complete End to End Deep Learning Project With MLFLOW,DVC And Deployment/Kidney-Disease-MLOps-Project/main.py", line 14, in <module>
    data_ingestion.main()
  File "/media/liganium/Data/Complete End to End Deep Learning Project With MLFLOW,DVC And Deployment/Kidney-Disease-MLOps-Project/src/cnnClassifier/pipeline/stage_01_data_ingestion.py", line 16, in main
    data_ingestion.download_file()
  File "/media/liganium/Data/Complete End to End Deep Learning Project With MLFLOW,DVC And Deployment/Kidney-Disease-MLOps-Project/src/cnnClassifier/components/data_ingestion.py", line 33, in download_file
    raise e
  File "/media/liganium/Data/Complete End to End Deep Learning Project With MLFLOW,DVC And Deployment/Kidney-Disease-MLOps-Project/src/cnnClassifier/components/data_ingestion.py", line 28, in download_file
    gdown.download(prefix+file_id,zip_download_dir)
  File "/media/liganium/Data/Complete End to End Deep Learning Project With MLFLOW,DVC And Deployment/Kidney-Disease-MLOps-Project/kidney_env/lib/python3.12/site-packages/gdown/download.py", line 202, in download
    res = sess.get(url, stream=True, verify=verify)
          ^^^^^^^^^^^^^^^^^^^^^^^^^^^^^^^^^^^^^^^^^
  File "/media/liganium/Data/Complete End to End Deep Learning Project With MLFLOW,DVC And Deployment/Kidney-Disease-MLOps-Project/kidney_env/lib/python3.12/site-packages/requests/sessions.py", line 602, in get
    return self.request("GET", url, **kwargs)
           ^^^^^^^^^^^^^^^^^^^^^^^^^^^^^^^^^^
  File "/media/liganium/Data/Complete End to End Deep Learning Project With MLFLOW,DVC And Deployment/Kidney-Disease-MLOps-Project/kidney_env/lib/python3.12/site-packages/requests/sessions.py", line 589, in request
    resp = self.send(prep, **send_kwargs)
           ^^^^^^^^^^^^^^^^^^^^^^^^^^^^^^
  File "/media/liganium/Data/Complete End to End Deep Learning Project With MLFLOW,DVC And Deployment/Kidney-Disease-MLOps-Project/kidney_env/lib/python3.12/site-packages/requests/sessions.py", line 703, in send
    r = adapter.send(request, **kwargs)
        ^^^^^^^^^^^^^^^^^^^^^^^^^^^^^^^
  File "/media/liganium/Data/Complete End to End Deep Learning Project With MLFLOW,DVC And Deployment/Kidney-Disease-MLOps-Project/kidney_env/lib/python3.12/site-packages/requests/adapters.py", line 700, in send
    raise ConnectionError(e, request=request)
requests.exceptions.ConnectionError: HTTPSConnectionPool(host='drive.google.com', port=443): Max retries exceeded with url: /uc?/export=download&id=1C9K6JMeGAbG7jmY8ag1YRMbrHW8q0vQg (Caused by NewConnectionError('<urllib3.connection.HTTPSConnection object at 0x7cdd3fc53b00>: Failed to establish a new connection: [Errno 101] Network is unreachable'))
[2025-05-11 22:09:53,071: INFO: main: >>>>>> stage Data Ingestion stage started <<<<<<]
[2025-05-11 22:09:53,072: INFO: common: yaml file: config/config.yaml loaded successfully]
[2025-05-11 22:09:53,073: INFO: common: yaml file: params.yaml loaded successfully]
[2025-05-11 22:09:53,074: INFO: common: created directory at: artifacts]
[2025-05-11 22:09:53,074: INFO: common: created directory at: artifacts/data_ingestion]
[2025-05-11 22:09:53,074: INFO: data_ingestion: Downloading data from https://drive.google.com/file/d/1C9K6JMeGAbG7jmY8ag1YRMbrHW8q0vQg/view?usp=sharing into file artifacts/data_ingestion/data.zip]
[2025-05-11 22:12:06,944: ERROR: main: HTTPSConnectionPool(host='drive.google.com', port=443): Max retries exceeded with url: /uc?/export=download&id=1C9K6JMeGAbG7jmY8ag1YRMbrHW8q0vQg (Caused by NewConnectionError('<urllib3.connection.HTTPSConnection object at 0x78bc002805c0>: Failed to establish a new connection: [Errno 101] Network is unreachable'))]
Traceback (most recent call last):
  File "/media/liganium/Data/Complete End to End Deep Learning Project With MLFLOW,DVC And Deployment/Kidney-Disease-MLOps-Project/kidney_env/lib/python3.12/site-packages/urllib3/connection.py", line 198, in _new_conn
    sock = connection.create_connection(
           ^^^^^^^^^^^^^^^^^^^^^^^^^^^^^
  File "/media/liganium/Data/Complete End to End Deep Learning Project With MLFLOW,DVC And Deployment/Kidney-Disease-MLOps-Project/kidney_env/lib/python3.12/site-packages/urllib3/util/connection.py", line 85, in create_connection
    raise err
  File "/media/liganium/Data/Complete End to End Deep Learning Project With MLFLOW,DVC And Deployment/Kidney-Disease-MLOps-Project/kidney_env/lib/python3.12/site-packages/urllib3/util/connection.py", line 73, in create_connection
    sock.connect(sa)
OSError: [Errno 101] Network is unreachable

The above exception was the direct cause of the following exception:

Traceback (most recent call last):
  File "/media/liganium/Data/Complete End to End Deep Learning Project With MLFLOW,DVC And Deployment/Kidney-Disease-MLOps-Project/kidney_env/lib/python3.12/site-packages/urllib3/connectionpool.py", line 787, in urlopen
    response = self._make_request(
               ^^^^^^^^^^^^^^^^^^^
  File "/media/liganium/Data/Complete End to End Deep Learning Project With MLFLOW,DVC And Deployment/Kidney-Disease-MLOps-Project/kidney_env/lib/python3.12/site-packages/urllib3/connectionpool.py", line 488, in _make_request
    raise new_e
  File "/media/liganium/Data/Complete End to End Deep Learning Project With MLFLOW,DVC And Deployment/Kidney-Disease-MLOps-Project/kidney_env/lib/python3.12/site-packages/urllib3/connectionpool.py", line 464, in _make_request
    self._validate_conn(conn)
  File "/media/liganium/Data/Complete End to End Deep Learning Project With MLFLOW,DVC And Deployment/Kidney-Disease-MLOps-Project/kidney_env/lib/python3.12/site-packages/urllib3/connectionpool.py", line 1093, in _validate_conn
    conn.connect()
  File "/media/liganium/Data/Complete End to End Deep Learning Project With MLFLOW,DVC And Deployment/Kidney-Disease-MLOps-Project/kidney_env/lib/python3.12/site-packages/urllib3/connection.py", line 704, in connect
    self.sock = sock = self._new_conn()
                       ^^^^^^^^^^^^^^^^
  File "/media/liganium/Data/Complete End to End Deep Learning Project With MLFLOW,DVC And Deployment/Kidney-Disease-MLOps-Project/kidney_env/lib/python3.12/site-packages/urllib3/connection.py", line 213, in _new_conn
    raise NewConnectionError(
urllib3.exceptions.NewConnectionError: <urllib3.connection.HTTPSConnection object at 0x78bc002805c0>: Failed to establish a new connection: [Errno 101] Network is unreachable

The above exception was the direct cause of the following exception:

Traceback (most recent call last):
  File "/media/liganium/Data/Complete End to End Deep Learning Project With MLFLOW,DVC And Deployment/Kidney-Disease-MLOps-Project/kidney_env/lib/python3.12/site-packages/requests/adapters.py", line 667, in send
    resp = conn.urlopen(
           ^^^^^^^^^^^^^
  File "/media/liganium/Data/Complete End to End Deep Learning Project With MLFLOW,DVC And Deployment/Kidney-Disease-MLOps-Project/kidney_env/lib/python3.12/site-packages/urllib3/connectionpool.py", line 841, in urlopen
    retries = retries.increment(
              ^^^^^^^^^^^^^^^^^^
  File "/media/liganium/Data/Complete End to End Deep Learning Project With MLFLOW,DVC And Deployment/Kidney-Disease-MLOps-Project/kidney_env/lib/python3.12/site-packages/urllib3/util/retry.py", line 519, in increment
    raise MaxRetryError(_pool, url, reason) from reason  # type: ignore[arg-type]
    ^^^^^^^^^^^^^^^^^^^^^^^^^^^^^^^^^^^^^^^^^^^^^^^^^^^
urllib3.exceptions.MaxRetryError: HTTPSConnectionPool(host='drive.google.com', port=443): Max retries exceeded with url: /uc?/export=download&id=1C9K6JMeGAbG7jmY8ag1YRMbrHW8q0vQg (Caused by NewConnectionError('<urllib3.connection.HTTPSConnection object at 0x78bc002805c0>: Failed to establish a new connection: [Errno 101] Network is unreachable'))

During handling of the above exception, another exception occurred:

Traceback (most recent call last):
  File "/media/liganium/Data/Complete End to End Deep Learning Project With MLFLOW,DVC And Deployment/Kidney-Disease-MLOps-Project/main.py", line 14, in <module>
    data_ingestion.main()
  File "/media/liganium/Data/Complete End to End Deep Learning Project With MLFLOW,DVC And Deployment/Kidney-Disease-MLOps-Project/src/cnnClassifier/pipeline/stage_01_data_ingestion.py", line 16, in main
    data_ingestion.download_file()
  File "/media/liganium/Data/Complete End to End Deep Learning Project With MLFLOW,DVC And Deployment/Kidney-Disease-MLOps-Project/src/cnnClassifier/components/data_ingestion.py", line 33, in download_file
    raise e
  File "/media/liganium/Data/Complete End to End Deep Learning Project With MLFLOW,DVC And Deployment/Kidney-Disease-MLOps-Project/src/cnnClassifier/components/data_ingestion.py", line 28, in download_file
    gdown.download(prefix+file_id,zip_download_dir)
  File "/media/liganium/Data/Complete End to End Deep Learning Project With MLFLOW,DVC And Deployment/Kidney-Disease-MLOps-Project/kidney_env/lib/python3.12/site-packages/gdown/download.py", line 202, in download
    res = sess.get(url, stream=True, verify=verify)
          ^^^^^^^^^^^^^^^^^^^^^^^^^^^^^^^^^^^^^^^^^
  File "/media/liganium/Data/Complete End to End Deep Learning Project With MLFLOW,DVC And Deployment/Kidney-Disease-MLOps-Project/kidney_env/lib/python3.12/site-packages/requests/sessions.py", line 602, in get
    return self.request("GET", url, **kwargs)
           ^^^^^^^^^^^^^^^^^^^^^^^^^^^^^^^^^^
  File "/media/liganium/Data/Complete End to End Deep Learning Project With MLFLOW,DVC And Deployment/Kidney-Disease-MLOps-Project/kidney_env/lib/python3.12/site-packages/requests/sessions.py", line 589, in request
    resp = self.send(prep, **send_kwargs)
           ^^^^^^^^^^^^^^^^^^^^^^^^^^^^^^
  File "/media/liganium/Data/Complete End to End Deep Learning Project With MLFLOW,DVC And Deployment/Kidney-Disease-MLOps-Project/kidney_env/lib/python3.12/site-packages/requests/sessions.py", line 703, in send
    r = adapter.send(request, **kwargs)
        ^^^^^^^^^^^^^^^^^^^^^^^^^^^^^^^
  File "/media/liganium/Data/Complete End to End Deep Learning Project With MLFLOW,DVC And Deployment/Kidney-Disease-MLOps-Project/kidney_env/lib/python3.12/site-packages/requests/adapters.py", line 700, in send
    raise ConnectionError(e, request=request)
requests.exceptions.ConnectionError: HTTPSConnectionPool(host='drive.google.com', port=443): Max retries exceeded with url: /uc?/export=download&id=1C9K6JMeGAbG7jmY8ag1YRMbrHW8q0vQg (Caused by NewConnectionError('<urllib3.connection.HTTPSConnection object at 0x78bc002805c0>: Failed to establish a new connection: [Errno 101] Network is unreachable'))
[2025-05-11 22:15:20,363: INFO: main: >>>>>> stage Data Ingestion stage started <<<<<<]
[2025-05-11 22:15:20,365: INFO: common: yaml file: config/config.yaml loaded successfully]
[2025-05-11 22:15:20,366: INFO: common: yaml file: params.yaml loaded successfully]
[2025-05-11 22:15:20,366: INFO: common: created directory at: artifacts]
[2025-05-11 22:15:20,366: INFO: common: created directory at: artifacts/data_ingestion]
[2025-05-11 22:15:20,366: INFO: data_ingestion: Downloading data from https://drive.google.com/file/d/1C9K6JMeGAbG7jmY8ag1YRMbrHW8q0vQg/view?usp=sharing into file artifacts/data_ingestion/data.zip]
[2025-05-11 22:16:30,222: INFO: data_ingestion: Downloaded data from https://drive.google.com/file/d/1C9K6JMeGAbG7jmY8ag1YRMbrHW8q0vQg/view?usp=sharing into file artifacts/data_ingestion/data.zip]
[2025-05-11 22:16:44,920: INFO: main: >>>>>> stage Data Ingestion stage completed <<<<<<

x==========x]
[2025-05-11 23:07:50,918: INFO: main: >>>>>> stage Data Ingestion stage started <<<<<<]
[2025-05-11 23:07:50,921: INFO: common: yaml file: config/config.yaml loaded successfully]
[2025-05-11 23:07:50,923: INFO: common: yaml file: params.yaml loaded successfully]
[2025-05-11 23:07:50,923: INFO: common: created directory at: artifacts]
[2025-05-11 23:07:50,923: INFO: common: created directory at: artifacts/data_ingestion]
[2025-05-11 23:07:50,923: INFO: data_ingestion: Downloading data from https://drive.google.com/file/d/1C9K6JMeGAbG7jmY8ag1YRMbrHW8q0vQg/view?usp=sharing into file artifacts/data_ingestion/data.zip]
[2025-05-11 23:09:12,944: INFO: main: *******************]
[2025-05-11 23:09:12,944: INFO: main: >>>>>> stage Prepare base model started <<<<<<]
[2025-05-11 23:09:12,945: INFO: common: yaml file: config/config.yaml loaded successfully]
[2025-05-11 23:09:12,946: INFO: common: yaml file: params.yaml loaded successfully]
[2025-05-11 23:09:12,946: INFO: common: created directory at: artifacts]
[2025-05-11 23:09:12,946: INFO: common: created directory at: artifacts/prepare_base_model]
[2025-05-11 23:09:18,035: WARNING: saving_api: You are saving your model as an HDF5 file via `model.save()` or `keras.saving.save_model(model)`. This file format is considered legacy. We recommend using instead the native Keras format, e.g. `model.save('my_model.keras')` or `keras.saving.save_model(model, 'my_model.keras')`. ]
[2025-05-11 23:09:18,188: WARNING: saving_api: You are saving your model as an HDF5 file via `model.save()` or `keras.saving.save_model(model)`. This file format is considered legacy. We recommend using instead the native Keras format, e.g. `model.save('my_model.keras')` or `keras.saving.save_model(model, 'my_model.keras')`. ]
[2025-05-11 23:09:18,308: INFO: main: >>>>>> stage Prepare base model completed <<<<<<

x==========x]
[2025-05-11 23:44:44,743: INFO: main: *******************]
[2025-05-11 23:44:44,743: INFO: main: >>>>>> stage Prepare base model started <<<<<<]
[2025-05-11 23:44:44,745: INFO: common: yaml file: config/config.yaml loaded successfully]
[2025-05-11 23:44:44,746: INFO: common: yaml file: params.yaml loaded successfully]
[2025-05-11 23:44:44,746: INFO: common: created directory at: artifacts]
[2025-05-11 23:44:44,746: INFO: common: created directory at: artifacts/prepare_base_model]
[2025-05-11 23:44:46,756: WARNING: saving_api: You are saving your model as an HDF5 file via `model.save()` or `keras.saving.save_model(model)`. This file format is considered legacy. We recommend using instead the native Keras format, e.g. `model.save('my_model.keras')` or `keras.saving.save_model(model, 'my_model.keras')`. ]
[2025-05-11 23:44:46,913: WARNING: saving_api: You are saving your model as an HDF5 file via `model.save()` or `keras.saving.save_model(model)`. This file format is considered legacy. We recommend using instead the native Keras format, e.g. `model.save('my_model.keras')` or `keras.saving.save_model(model, 'my_model.keras')`. ]
[2025-05-11 23:44:47,044: INFO: main: >>>>>> stage Prepare base model completed <<<<<<

x==========x]
[2025-05-11 23:44:47,045: INFO: main: *******************]
[2025-05-11 23:44:47,045: INFO: main: >>>>>> stage Training started <<<<<<]
[2025-05-11 23:44:47,046: INFO: common: yaml file: config/config.yaml loaded successfully]
[2025-05-11 23:44:47,047: INFO: common: yaml file: params.yaml loaded successfully]
[2025-05-11 23:44:47,048: INFO: common: created directory at: artifacts]
[2025-05-11 23:44:47,048: INFO: common: created directory at: artifacts/training]
[2025-05-11 23:44:47,213: WARNING: saving_utils: Compiled the loaded model, but the compiled metrics have yet to be built. `model.compile_metrics` will be empty until you train or evaluate the model.]
[2025-05-11 23:44:47,217: ERROR: main: [Errno 2] No such file or directory: 'artifacts/data_ingestion/kidney-ct-scan-image']
Traceback (most recent call last):
  File "/media/liganium/Data/Complete End to End Deep Learning Project With MLFLOW,DVC And Deployment/Kidney-Disease-MLOps-Project/main.py", line 42, in <module>
    model_trainer.main()
  File "/media/liganium/Data/Complete End to End Deep Learning Project With MLFLOW,DVC And Deployment/Kidney-Disease-MLOps-Project/src/cnnClassifier/pipeline/stage_03_model_training.py", line 20, in main
    training.train_valid_generator()
  File "/media/liganium/Data/Complete End to End Deep Learning Project With MLFLOW,DVC And Deployment/Kidney-Disease-MLOps-Project/src/cnnClassifier/components/model_training.py", line 37, in train_valid_generator
    self.valid_generator = valid_datagenerator.flow_from_directory(
                           ^^^^^^^^^^^^^^^^^^^^^^^^^^^^^^^^^^^^^^^^
  File "/media/liganium/Data/Complete End to End Deep Learning Project With MLFLOW,DVC And Deployment/Kidney-Disease-MLOps-Project/kidney_env/lib/python3.12/site-packages/keras/src/legacy/preprocessing/image.py", line 1138, in flow_from_directory
    return DirectoryIterator(
           ^^^^^^^^^^^^^^^^^^
  File "/media/liganium/Data/Complete End to End Deep Learning Project With MLFLOW,DVC And Deployment/Kidney-Disease-MLOps-Project/kidney_env/lib/python3.12/site-packages/keras/src/legacy/preprocessing/image.py", line 453, in __init__
    for subdir in sorted(os.listdir(directory)):
                         ^^^^^^^^^^^^^^^^^^^^^
FileNotFoundError: [Errno 2] No such file or directory: 'artifacts/data_ingestion/kidney-ct-scan-image'
[2025-05-12 00:03:44,228: INFO: main: >>>>>> stage Data Ingestion stage started <<<<<<]
[2025-05-12 00:03:44,229: INFO: common: yaml file: config/config.yaml loaded successfully]
[2025-05-12 00:03:44,230: INFO: common: yaml file: params.yaml loaded successfully]
[2025-05-12 00:03:44,231: INFO: common: created directory at: artifacts]
[2025-05-12 00:03:44,231: INFO: common: created directory at: artifacts/data_ingestion]
[2025-05-12 00:03:44,231: INFO: data_ingestion: Downloading data from https://drive.google.com/file/d/1C9K6JMeGAbG7jmY8ag1YRMbrHW8q0vQg/view?usp=sharing into file artifacts/data_ingestion/data.zip]
[2025-05-12 00:06:00,669: ERROR: main: HTTPSConnectionPool(host='drive.google.com', port=443): Max retries exceeded with url: /uc?/export=download&id=1C9K6JMeGAbG7jmY8ag1YRMbrHW8q0vQg (Caused by NewConnectionError('<urllib3.connection.HTTPSConnection object at 0x7f1dbf337c20>: Failed to establish a new connection: [Errno 101] Network is unreachable'))]
Traceback (most recent call last):
  File "/media/liganium/Data/Complete End to End Deep Learning Project With MLFLOW,DVC And Deployment/Kidney-Disease-MLOps-Project/kidney_env/lib/python3.12/site-packages/urllib3/connection.py", line 198, in _new_conn
    sock = connection.create_connection(
           ^^^^^^^^^^^^^^^^^^^^^^^^^^^^^
  File "/media/liganium/Data/Complete End to End Deep Learning Project With MLFLOW,DVC And Deployment/Kidney-Disease-MLOps-Project/kidney_env/lib/python3.12/site-packages/urllib3/util/connection.py", line 85, in create_connection
    raise err
  File "/media/liganium/Data/Complete End to End Deep Learning Project With MLFLOW,DVC And Deployment/Kidney-Disease-MLOps-Project/kidney_env/lib/python3.12/site-packages/urllib3/util/connection.py", line 73, in create_connection
    sock.connect(sa)
OSError: [Errno 101] Network is unreachable

The above exception was the direct cause of the following exception:

Traceback (most recent call last):
  File "/media/liganium/Data/Complete End to End Deep Learning Project With MLFLOW,DVC And Deployment/Kidney-Disease-MLOps-Project/kidney_env/lib/python3.12/site-packages/urllib3/connectionpool.py", line 787, in urlopen
    response = self._make_request(
               ^^^^^^^^^^^^^^^^^^^
  File "/media/liganium/Data/Complete End to End Deep Learning Project With MLFLOW,DVC And Deployment/Kidney-Disease-MLOps-Project/kidney_env/lib/python3.12/site-packages/urllib3/connectionpool.py", line 488, in _make_request
    raise new_e
  File "/media/liganium/Data/Complete End to End Deep Learning Project With MLFLOW,DVC And Deployment/Kidney-Disease-MLOps-Project/kidney_env/lib/python3.12/site-packages/urllib3/connectionpool.py", line 464, in _make_request
    self._validate_conn(conn)
  File "/media/liganium/Data/Complete End to End Deep Learning Project With MLFLOW,DVC And Deployment/Kidney-Disease-MLOps-Project/kidney_env/lib/python3.12/site-packages/urllib3/connectionpool.py", line 1093, in _validate_conn
    conn.connect()
  File "/media/liganium/Data/Complete End to End Deep Learning Project With MLFLOW,DVC And Deployment/Kidney-Disease-MLOps-Project/kidney_env/lib/python3.12/site-packages/urllib3/connection.py", line 704, in connect
    self.sock = sock = self._new_conn()
                       ^^^^^^^^^^^^^^^^
  File "/media/liganium/Data/Complete End to End Deep Learning Project With MLFLOW,DVC And Deployment/Kidney-Disease-MLOps-Project/kidney_env/lib/python3.12/site-packages/urllib3/connection.py", line 213, in _new_conn
    raise NewConnectionError(
urllib3.exceptions.NewConnectionError: <urllib3.connection.HTTPSConnection object at 0x7f1dbf337c20>: Failed to establish a new connection: [Errno 101] Network is unreachable

The above exception was the direct cause of the following exception:

Traceback (most recent call last):
  File "/media/liganium/Data/Complete End to End Deep Learning Project With MLFLOW,DVC And Deployment/Kidney-Disease-MLOps-Project/kidney_env/lib/python3.12/site-packages/requests/adapters.py", line 667, in send
    resp = conn.urlopen(
           ^^^^^^^^^^^^^
  File "/media/liganium/Data/Complete End to End Deep Learning Project With MLFLOW,DVC And Deployment/Kidney-Disease-MLOps-Project/kidney_env/lib/python3.12/site-packages/urllib3/connectionpool.py", line 841, in urlopen
    retries = retries.increment(
              ^^^^^^^^^^^^^^^^^^
  File "/media/liganium/Data/Complete End to End Deep Learning Project With MLFLOW,DVC And Deployment/Kidney-Disease-MLOps-Project/kidney_env/lib/python3.12/site-packages/urllib3/util/retry.py", line 519, in increment
    raise MaxRetryError(_pool, url, reason) from reason  # type: ignore[arg-type]
    ^^^^^^^^^^^^^^^^^^^^^^^^^^^^^^^^^^^^^^^^^^^^^^^^^^^
urllib3.exceptions.MaxRetryError: HTTPSConnectionPool(host='drive.google.com', port=443): Max retries exceeded with url: /uc?/export=download&id=1C9K6JMeGAbG7jmY8ag1YRMbrHW8q0vQg (Caused by NewConnectionError('<urllib3.connection.HTTPSConnection object at 0x7f1dbf337c20>: Failed to establish a new connection: [Errno 101] Network is unreachable'))

During handling of the above exception, another exception occurred:

Traceback (most recent call last):
  File "/media/liganium/Data/Complete End to End Deep Learning Project With MLFLOW,DVC And Deployment/Kidney-Disease-MLOps-Project/main.py", line 14, in <module>
    data_ingestion.main()
  File "/media/liganium/Data/Complete End to End Deep Learning Project With MLFLOW,DVC And Deployment/Kidney-Disease-MLOps-Project/src/cnnClassifier/pipeline/stage_01_data_ingestion.py", line 16, in main
    data_ingestion.download_file()
  File "/media/liganium/Data/Complete End to End Deep Learning Project With MLFLOW,DVC And Deployment/Kidney-Disease-MLOps-Project/src/cnnClassifier/components/data_ingestion.py", line 33, in download_file
    raise e
  File "/media/liganium/Data/Complete End to End Deep Learning Project With MLFLOW,DVC And Deployment/Kidney-Disease-MLOps-Project/src/cnnClassifier/components/data_ingestion.py", line 28, in download_file
    gdown.download(prefix+file_id,zip_download_dir)
  File "/media/liganium/Data/Complete End to End Deep Learning Project With MLFLOW,DVC And Deployment/Kidney-Disease-MLOps-Project/kidney_env/lib/python3.12/site-packages/gdown/download.py", line 202, in download
    res = sess.get(url, stream=True, verify=verify)
          ^^^^^^^^^^^^^^^^^^^^^^^^^^^^^^^^^^^^^^^^^
  File "/media/liganium/Data/Complete End to End Deep Learning Project With MLFLOW,DVC And Deployment/Kidney-Disease-MLOps-Project/kidney_env/lib/python3.12/site-packages/requests/sessions.py", line 602, in get
    return self.request("GET", url, **kwargs)
           ^^^^^^^^^^^^^^^^^^^^^^^^^^^^^^^^^^
  File "/media/liganium/Data/Complete End to End Deep Learning Project With MLFLOW,DVC And Deployment/Kidney-Disease-MLOps-Project/kidney_env/lib/python3.12/site-packages/requests/sessions.py", line 589, in request
    resp = self.send(prep, **send_kwargs)
           ^^^^^^^^^^^^^^^^^^^^^^^^^^^^^^
  File "/media/liganium/Data/Complete End to End Deep Learning Project With MLFLOW,DVC And Deployment/Kidney-Disease-MLOps-Project/kidney_env/lib/python3.12/site-packages/requests/sessions.py", line 703, in send
    r = adapter.send(request, **kwargs)
        ^^^^^^^^^^^^^^^^^^^^^^^^^^^^^^^
  File "/media/liganium/Data/Complete End to End Deep Learning Project With MLFLOW,DVC And Deployment/Kidney-Disease-MLOps-Project/kidney_env/lib/python3.12/site-packages/requests/adapters.py", line 700, in send
    raise ConnectionError(e, request=request)
requests.exceptions.ConnectionError: HTTPSConnectionPool(host='drive.google.com', port=443): Max retries exceeded with url: /uc?/export=download&id=1C9K6JMeGAbG7jmY8ag1YRMbrHW8q0vQg (Caused by NewConnectionError('<urllib3.connection.HTTPSConnection object at 0x7f1dbf337c20>: Failed to establish a new connection: [Errno 101] Network is unreachable'))
[2025-05-12 00:07:51,747: INFO: main: >>>>>> stage Data Ingestion stage started <<<<<<]
[2025-05-12 00:07:51,749: INFO: common: yaml file: config/config.yaml loaded successfully]
[2025-05-12 00:07:51,750: INFO: common: yaml file: params.yaml loaded successfully]
[2025-05-12 00:07:51,750: INFO: common: created directory at: artifacts]
[2025-05-12 00:07:51,751: INFO: common: created directory at: artifacts/data_ingestion]
[2025-05-12 00:07:51,751: INFO: data_ingestion: Downloading data from https://drive.google.com/file/d/1C9K6JMeGAbG7jmY8ag1YRMbrHW8q0vQg/view?usp=sharing into file artifacts/data_ingestion/data.zip]
[2025-05-12 00:10:06,429: ERROR: main: HTTPSConnectionPool(host='drive.google.com', port=443): Max retries exceeded with url: /uc?/export=download&id=1C9K6JMeGAbG7jmY8ag1YRMbrHW8q0vQg (Caused by NewConnectionError('<urllib3.connection.HTTPSConnection object at 0x72c5c618ca10>: Failed to establish a new connection: [Errno 101] Network is unreachable'))]
Traceback (most recent call last):
  File "/media/liganium/Data/Complete End to End Deep Learning Project With MLFLOW,DVC And Deployment/Kidney-Disease-MLOps-Project/kidney_env/lib/python3.12/site-packages/urllib3/connection.py", line 198, in _new_conn
    sock = connection.create_connection(
           ^^^^^^^^^^^^^^^^^^^^^^^^^^^^^
  File "/media/liganium/Data/Complete End to End Deep Learning Project With MLFLOW,DVC And Deployment/Kidney-Disease-MLOps-Project/kidney_env/lib/python3.12/site-packages/urllib3/util/connection.py", line 85, in create_connection
    raise err
  File "/media/liganium/Data/Complete End to End Deep Learning Project With MLFLOW,DVC And Deployment/Kidney-Disease-MLOps-Project/kidney_env/lib/python3.12/site-packages/urllib3/util/connection.py", line 73, in create_connection
    sock.connect(sa)
OSError: [Errno 101] Network is unreachable

The above exception was the direct cause of the following exception:

Traceback (most recent call last):
  File "/media/liganium/Data/Complete End to End Deep Learning Project With MLFLOW,DVC And Deployment/Kidney-Disease-MLOps-Project/kidney_env/lib/python3.12/site-packages/urllib3/connectionpool.py", line 787, in urlopen
    response = self._make_request(
               ^^^^^^^^^^^^^^^^^^^
  File "/media/liganium/Data/Complete End to End Deep Learning Project With MLFLOW,DVC And Deployment/Kidney-Disease-MLOps-Project/kidney_env/lib/python3.12/site-packages/urllib3/connectionpool.py", line 488, in _make_request
    raise new_e
  File "/media/liganium/Data/Complete End to End Deep Learning Project With MLFLOW,DVC And Deployment/Kidney-Disease-MLOps-Project/kidney_env/lib/python3.12/site-packages/urllib3/connectionpool.py", line 464, in _make_request
    self._validate_conn(conn)
  File "/media/liganium/Data/Complete End to End Deep Learning Project With MLFLOW,DVC And Deployment/Kidney-Disease-MLOps-Project/kidney_env/lib/python3.12/site-packages/urllib3/connectionpool.py", line 1093, in _validate_conn
    conn.connect()
  File "/media/liganium/Data/Complete End to End Deep Learning Project With MLFLOW,DVC And Deployment/Kidney-Disease-MLOps-Project/kidney_env/lib/python3.12/site-packages/urllib3/connection.py", line 704, in connect
    self.sock = sock = self._new_conn()
                       ^^^^^^^^^^^^^^^^
  File "/media/liganium/Data/Complete End to End Deep Learning Project With MLFLOW,DVC And Deployment/Kidney-Disease-MLOps-Project/kidney_env/lib/python3.12/site-packages/urllib3/connection.py", line 213, in _new_conn
    raise NewConnectionError(
urllib3.exceptions.NewConnectionError: <urllib3.connection.HTTPSConnection object at 0x72c5c618ca10>: Failed to establish a new connection: [Errno 101] Network is unreachable

The above exception was the direct cause of the following exception:

Traceback (most recent call last):
  File "/media/liganium/Data/Complete End to End Deep Learning Project With MLFLOW,DVC And Deployment/Kidney-Disease-MLOps-Project/kidney_env/lib/python3.12/site-packages/requests/adapters.py", line 667, in send
    resp = conn.urlopen(
           ^^^^^^^^^^^^^
  File "/media/liganium/Data/Complete End to End Deep Learning Project With MLFLOW,DVC And Deployment/Kidney-Disease-MLOps-Project/kidney_env/lib/python3.12/site-packages/urllib3/connectionpool.py", line 841, in urlopen
    retries = retries.increment(
              ^^^^^^^^^^^^^^^^^^
  File "/media/liganium/Data/Complete End to End Deep Learning Project With MLFLOW,DVC And Deployment/Kidney-Disease-MLOps-Project/kidney_env/lib/python3.12/site-packages/urllib3/util/retry.py", line 519, in increment
    raise MaxRetryError(_pool, url, reason) from reason  # type: ignore[arg-type]
    ^^^^^^^^^^^^^^^^^^^^^^^^^^^^^^^^^^^^^^^^^^^^^^^^^^^
urllib3.exceptions.MaxRetryError: HTTPSConnectionPool(host='drive.google.com', port=443): Max retries exceeded with url: /uc?/export=download&id=1C9K6JMeGAbG7jmY8ag1YRMbrHW8q0vQg (Caused by NewConnectionError('<urllib3.connection.HTTPSConnection object at 0x72c5c618ca10>: Failed to establish a new connection: [Errno 101] Network is unreachable'))

During handling of the above exception, another exception occurred:

Traceback (most recent call last):
  File "/media/liganium/Data/Complete End to End Deep Learning Project With MLFLOW,DVC And Deployment/Kidney-Disease-MLOps-Project/main.py", line 14, in <module>
    data_ingestion.main()
  File "/media/liganium/Data/Complete End to End Deep Learning Project With MLFLOW,DVC And Deployment/Kidney-Disease-MLOps-Project/src/cnnClassifier/pipeline/stage_01_data_ingestion.py", line 16, in main
    data_ingestion.download_file()
  File "/media/liganium/Data/Complete End to End Deep Learning Project With MLFLOW,DVC And Deployment/Kidney-Disease-MLOps-Project/src/cnnClassifier/components/data_ingestion.py", line 33, in download_file
    raise e
  File "/media/liganium/Data/Complete End to End Deep Learning Project With MLFLOW,DVC And Deployment/Kidney-Disease-MLOps-Project/src/cnnClassifier/components/data_ingestion.py", line 28, in download_file
    gdown.download(prefix+file_id,zip_download_dir)
  File "/media/liganium/Data/Complete End to End Deep Learning Project With MLFLOW,DVC And Deployment/Kidney-Disease-MLOps-Project/kidney_env/lib/python3.12/site-packages/gdown/download.py", line 202, in download
    res = sess.get(url, stream=True, verify=verify)
          ^^^^^^^^^^^^^^^^^^^^^^^^^^^^^^^^^^^^^^^^^
  File "/media/liganium/Data/Complete End to End Deep Learning Project With MLFLOW,DVC And Deployment/Kidney-Disease-MLOps-Project/kidney_env/lib/python3.12/site-packages/requests/sessions.py", line 602, in get
    return self.request("GET", url, **kwargs)
           ^^^^^^^^^^^^^^^^^^^^^^^^^^^^^^^^^^
  File "/media/liganium/Data/Complete End to End Deep Learning Project With MLFLOW,DVC And Deployment/Kidney-Disease-MLOps-Project/kidney_env/lib/python3.12/site-packages/requests/sessions.py", line 589, in request
    resp = self.send(prep, **send_kwargs)
           ^^^^^^^^^^^^^^^^^^^^^^^^^^^^^^
  File "/media/liganium/Data/Complete End to End Deep Learning Project With MLFLOW,DVC And Deployment/Kidney-Disease-MLOps-Project/kidney_env/lib/python3.12/site-packages/requests/sessions.py", line 703, in send
    r = adapter.send(request, **kwargs)
        ^^^^^^^^^^^^^^^^^^^^^^^^^^^^^^^
  File "/media/liganium/Data/Complete End to End Deep Learning Project With MLFLOW,DVC And Deployment/Kidney-Disease-MLOps-Project/kidney_env/lib/python3.12/site-packages/requests/adapters.py", line 700, in send
    raise ConnectionError(e, request=request)
requests.exceptions.ConnectionError: HTTPSConnectionPool(host='drive.google.com', port=443): Max retries exceeded with url: /uc?/export=download&id=1C9K6JMeGAbG7jmY8ag1YRMbrHW8q0vQg (Caused by NewConnectionError('<urllib3.connection.HTTPSConnection object at 0x72c5c618ca10>: Failed to establish a new connection: [Errno 101] Network is unreachable'))
[2025-05-12 00:11:40,737: INFO: main: >>>>>> stage Data Ingestion stage started <<<<<<]
[2025-05-12 00:11:40,738: INFO: common: yaml file: config/config.yaml loaded successfully]
[2025-05-12 00:11:40,740: INFO: common: yaml file: params.yaml loaded successfully]
[2025-05-12 00:11:40,740: INFO: common: created directory at: artifacts]
[2025-05-12 00:11:40,740: INFO: common: created directory at: artifacts/data_ingestion]
[2025-05-12 00:11:40,740: INFO: data_ingestion: Downloading data from https://drive.google.com/file/d/1C9K6JMeGAbG7jmY8ag1YRMbrHW8q0vQg/view?usp=sharing into file artifacts/data_ingestion/data.zip]
[2025-05-12 00:16:36,403: INFO: data_ingestion: Downloaded data from https://drive.google.com/file/d/1C9K6JMeGAbG7jmY8ag1YRMbrHW8q0vQg/view?usp=sharing into file artifacts/data_ingestion/data.zip]
[2025-05-12 00:16:52,808: INFO: main: >>>>>> stage Data Ingestion stage completed <<<<<<

x==========x]
[2025-05-12 00:16:52,808: INFO: main: *******************]
[2025-05-12 00:16:52,808: INFO: main: >>>>>> stage Prepare base model started <<<<<<]
[2025-05-12 00:16:52,810: INFO: common: yaml file: config/config.yaml loaded successfully]
[2025-05-12 00:16:52,811: INFO: common: yaml file: params.yaml loaded successfully]
[2025-05-12 00:16:52,811: INFO: common: created directory at: artifacts]
[2025-05-12 00:16:52,811: INFO: common: created directory at: artifacts/prepare_base_model]
[2025-05-12 00:16:53,566: WARNING: saving_api: You are saving your model as an HDF5 file via `model.save()` or `keras.saving.save_model(model)`. This file format is considered legacy. We recommend using instead the native Keras format, e.g. `model.save('my_model.keras')` or `keras.saving.save_model(model, 'my_model.keras')`. ]
[2025-05-12 00:16:53,724: WARNING: saving_api: You are saving your model as an HDF5 file via `model.save()` or `keras.saving.save_model(model)`. This file format is considered legacy. We recommend using instead the native Keras format, e.g. `model.save('my_model.keras')` or `keras.saving.save_model(model, 'my_model.keras')`. ]
[2025-05-12 00:16:53,840: INFO: main: >>>>>> stage Prepare base model completed <<<<<<

x==========x]
[2025-05-12 00:16:53,840: INFO: main: *******************]
[2025-05-12 00:16:53,840: INFO: main: >>>>>> stage Training started <<<<<<]
[2025-05-12 00:16:53,842: INFO: common: yaml file: config/config.yaml loaded successfully]
[2025-05-12 00:16:53,843: INFO: common: yaml file: params.yaml loaded successfully]
[2025-05-12 00:16:53,843: INFO: common: created directory at: artifacts]
[2025-05-12 00:16:53,844: INFO: common: created directory at: artifacts/training]
[2025-05-12 00:16:54,036: WARNING: saving_utils: Compiled the loaded model, but the compiled metrics have yet to be built. `model.compile_metrics` will be empty until you train or evaluate the model.]
[2025-05-12 00:16:54,041: ERROR: main: [Errno 2] No such file or directory: 'artifacts/data_ingestion/kidney-ct-scan-image']
Traceback (most recent call last):
  File "/media/liganium/Data/Complete End to End Deep Learning Project With MLFLOW,DVC And Deployment/Kidney-Disease-MLOps-Project/main.py", line 42, in <module>
    model_trainer.main()
  File "/media/liganium/Data/Complete End to End Deep Learning Project With MLFLOW,DVC And Deployment/Kidney-Disease-MLOps-Project/src/cnnClassifier/pipeline/stage_03_model_training.py", line 20, in main
    training.train_valid_generator()
  File "/media/liganium/Data/Complete End to End Deep Learning Project With MLFLOW,DVC And Deployment/Kidney-Disease-MLOps-Project/src/cnnClassifier/components/model_training.py", line 37, in train_valid_generator
    self.valid_generator = valid_datagenerator.flow_from_directory(
                           ^^^^^^^^^^^^^^^^^^^^^^^^^^^^^^^^^^^^^^^^
  File "/media/liganium/Data/Complete End to End Deep Learning Project With MLFLOW,DVC And Deployment/Kidney-Disease-MLOps-Project/kidney_env/lib/python3.12/site-packages/keras/src/legacy/preprocessing/image.py", line 1138, in flow_from_directory
    return DirectoryIterator(
           ^^^^^^^^^^^^^^^^^^
  File "/media/liganium/Data/Complete End to End Deep Learning Project With MLFLOW,DVC And Deployment/Kidney-Disease-MLOps-Project/kidney_env/lib/python3.12/site-packages/keras/src/legacy/preprocessing/image.py", line 453, in __init__
    for subdir in sorted(os.listdir(directory)):
                         ^^^^^^^^^^^^^^^^^^^^^
FileNotFoundError: [Errno 2] No such file or directory: 'artifacts/data_ingestion/kidney-ct-scan-image'
[2025-05-12 00:21:15,077: INFO: main: >>>>>> stage Data Ingestion stage started <<<<<<]
[2025-05-12 00:21:15,079: INFO: common: yaml file: config/config.yaml loaded successfully]
[2025-05-12 00:21:15,081: INFO: common: yaml file: params.yaml loaded successfully]
[2025-05-12 00:21:15,082: INFO: common: created directory at: artifacts]
[2025-05-12 00:21:15,082: INFO: common: created directory at: artifacts/data_ingestion]
[2025-05-12 00:21:15,082: INFO: data_ingestion: Downloading data from https://drive.google.com/file/d/17BJwWDAin2sJCpJ7-iZTba3OxNhv7vc-/view?usp=sharing into file artifacts/data_ingestion/data.zip]
[2025-05-12 00:21:57,807: INFO: data_ingestion: Downloaded data from https://drive.google.com/file/d/17BJwWDAin2sJCpJ7-iZTba3OxNhv7vc-/view?usp=sharing into file artifacts/data_ingestion/data.zip]
[2025-05-12 00:22:06,363: INFO: main: >>>>>> stage Data Ingestion stage completed <<<<<<

x==========x]
[2025-05-12 00:22:06,363: INFO: main: *******************]
[2025-05-12 00:22:06,363: INFO: main: >>>>>> stage Prepare base model started <<<<<<]
[2025-05-12 00:22:06,364: INFO: common: yaml file: config/config.yaml loaded successfully]
[2025-05-12 00:22:06,365: INFO: common: yaml file: params.yaml loaded successfully]
[2025-05-12 00:22:06,365: INFO: common: created directory at: artifacts]
[2025-05-12 00:22:06,365: INFO: common: created directory at: artifacts/prepare_base_model]
[2025-05-12 00:22:08,541: WARNING: saving_api: You are saving your model as an HDF5 file via `model.save()` or `keras.saving.save_model(model)`. This file format is considered legacy. We recommend using instead the native Keras format, e.g. `model.save('my_model.keras')` or `keras.saving.save_model(model, 'my_model.keras')`. ]
[2025-05-12 00:22:08,733: WARNING: saving_api: You are saving your model as an HDF5 file via `model.save()` or `keras.saving.save_model(model)`. This file format is considered legacy. We recommend using instead the native Keras format, e.g. `model.save('my_model.keras')` or `keras.saving.save_model(model, 'my_model.keras')`. ]
[2025-05-12 00:22:08,857: INFO: main: >>>>>> stage Prepare base model completed <<<<<<

x==========x]
[2025-05-12 00:22:08,857: INFO: main: *******************]
[2025-05-12 00:22:08,858: INFO: main: >>>>>> stage Training started <<<<<<]
[2025-05-12 00:22:08,859: INFO: common: yaml file: config/config.yaml loaded successfully]
[2025-05-12 00:22:08,860: INFO: common: yaml file: params.yaml loaded successfully]
[2025-05-12 00:22:08,860: INFO: common: created directory at: artifacts]
[2025-05-12 00:22:08,860: INFO: common: created directory at: artifacts/training]
[2025-05-12 00:22:09,045: WARNING: saving_utils: Compiled the loaded model, but the compiled metrics have yet to be built. `model.compile_metrics` will be empty until you train or evaluate the model.]
[2025-05-12 00:22:10,006: ERROR: main: numpy() is only available when eager execution is enabled.]
Traceback (most recent call last):
  File "/media/liganium/Data/Complete End to End Deep Learning Project With MLFLOW,DVC And Deployment/Kidney-Disease-MLOps-Project/main.py", line 42, in <module>
    model_trainer.main()
  File "/media/liganium/Data/Complete End to End Deep Learning Project With MLFLOW,DVC And Deployment/Kidney-Disease-MLOps-Project/src/cnnClassifier/pipeline/stage_03_model_training.py", line 21, in main
    training.train()
  File "/media/liganium/Data/Complete End to End Deep Learning Project With MLFLOW,DVC And Deployment/Kidney-Disease-MLOps-Project/src/cnnClassifier/components/model_training.py", line 76, in train
    self.model.fit(
  File "/media/liganium/Data/Complete End to End Deep Learning Project With MLFLOW,DVC And Deployment/Kidney-Disease-MLOps-Project/kidney_env/lib/python3.12/site-packages/keras/src/utils/traceback_utils.py", line 122, in error_handler
    raise e.with_traceback(filtered_tb) from None
  File "/media/liganium/Data/Complete End to End Deep Learning Project With MLFLOW,DVC And Deployment/Kidney-Disease-MLOps-Project/kidney_env/lib/python3.12/site-packages/keras/src/backend/tensorflow/core.py", line 158, in convert_to_numpy
    return np.array(x)
           ^^^^^^^^^^^
NotImplementedError: numpy() is only available when eager execution is enabled.
[2025-05-12 00:25:36,183: INFO: main: >>>>>> stage Data Ingestion stage started <<<<<<]
[2025-05-12 00:25:36,184: INFO: common: yaml file: config/config.yaml loaded successfully]
[2025-05-12 00:25:36,185: INFO: common: yaml file: params.yaml loaded successfully]
[2025-05-12 00:25:36,186: INFO: common: created directory at: artifacts]
[2025-05-12 00:25:36,186: INFO: common: created directory at: artifacts/data_ingestion]
[2025-05-12 00:25:36,186: INFO: data_ingestion: Downloading data from https://drive.google.com/file/d/17BJwWDAin2sJCpJ7-iZTba3OxNhv7vc-/view?usp=sharing into file artifacts/data_ingestion/data.zip]
[2025-05-12 00:26:07,904: INFO: main: *******************]
[2025-05-12 00:26:07,905: INFO: main: >>>>>> stage Prepare base model started <<<<<<]
[2025-05-12 00:26:07,906: INFO: common: yaml file: config/config.yaml loaded successfully]
[2025-05-12 00:26:07,907: INFO: common: yaml file: params.yaml loaded successfully]
[2025-05-12 00:26:07,907: INFO: common: created directory at: artifacts]
[2025-05-12 00:26:07,907: INFO: common: created directory at: artifacts/prepare_base_model]
[2025-05-12 00:26:09,925: WARNING: saving_api: You are saving your model as an HDF5 file via `model.save()` or `keras.saving.save_model(model)`. This file format is considered legacy. We recommend using instead the native Keras format, e.g. `model.save('my_model.keras')` or `keras.saving.save_model(model, 'my_model.keras')`. ]
[2025-05-12 00:26:10,084: WARNING: saving_api: You are saving your model as an HDF5 file via `model.save()` or `keras.saving.save_model(model)`. This file format is considered legacy. We recommend using instead the native Keras format, e.g. `model.save('my_model.keras')` or `keras.saving.save_model(model, 'my_model.keras')`. ]
[2025-05-12 00:26:10,207: INFO: main: >>>>>> stage Prepare base model completed <<<<<<

x==========x]
[2025-05-12 00:26:10,208: INFO: main: *******************]
[2025-05-12 00:26:10,208: INFO: main: >>>>>> stage Training started <<<<<<]
[2025-05-12 00:26:10,209: INFO: common: yaml file: config/config.yaml loaded successfully]
[2025-05-12 00:26:10,210: INFO: common: yaml file: params.yaml loaded successfully]
[2025-05-12 00:26:10,211: INFO: common: created directory at: artifacts]
[2025-05-12 00:26:10,211: INFO: common: created directory at: artifacts/training]
[2025-05-12 00:26:10,397: WARNING: saving_utils: Compiled the loaded model, but the compiled metrics have yet to be built. `model.compile_metrics` will be empty until you train or evaluate the model.]
[2025-05-12 00:26:11,273: ERROR: main: numpy() is only available when eager execution is enabled.]
Traceback (most recent call last):
  File "/media/liganium/Data/Complete End to End Deep Learning Project With MLFLOW,DVC And Deployment/Kidney-Disease-MLOps-Project/main.py", line 42, in <module>
    model_trainer.main()
  File "/media/liganium/Data/Complete End to End Deep Learning Project With MLFLOW,DVC And Deployment/Kidney-Disease-MLOps-Project/src/cnnClassifier/pipeline/stage_03_model_training.py", line 21, in main
    training.train()
  File "/media/liganium/Data/Complete End to End Deep Learning Project With MLFLOW,DVC And Deployment/Kidney-Disease-MLOps-Project/src/cnnClassifier/components/model_training.py", line 81, in train
    self.model.fit(
  File "/media/liganium/Data/Complete End to End Deep Learning Project With MLFLOW,DVC And Deployment/Kidney-Disease-MLOps-Project/kidney_env/lib/python3.12/site-packages/keras/src/utils/traceback_utils.py", line 122, in error_handler
    raise e.with_traceback(filtered_tb) from None
  File "/media/liganium/Data/Complete End to End Deep Learning Project With MLFLOW,DVC And Deployment/Kidney-Disease-MLOps-Project/kidney_env/lib/python3.12/site-packages/keras/src/backend/tensorflow/core.py", line 158, in convert_to_numpy
    return np.array(x)
           ^^^^^^^^^^^
NotImplementedError: numpy() is only available when eager execution is enabled.
[2025-05-12 00:30:00,703: INFO: main: *******************]
[2025-05-12 00:30:00,703: INFO: main: >>>>>> stage Prepare base model started <<<<<<]
[2025-05-12 00:30:00,705: INFO: common: yaml file: config/config.yaml loaded successfully]
[2025-05-12 00:30:00,706: INFO: common: yaml file: params.yaml loaded successfully]
[2025-05-12 00:30:00,706: INFO: common: created directory at: artifacts]
[2025-05-12 00:30:00,706: INFO: common: created directory at: artifacts/prepare_base_model]
[2025-05-12 00:30:02,680: WARNING: saving_api: You are saving your model as an HDF5 file via `model.save()` or `keras.saving.save_model(model)`. This file format is considered legacy. We recommend using instead the native Keras format, e.g. `model.save('my_model.keras')` or `keras.saving.save_model(model, 'my_model.keras')`. ]
[2025-05-12 00:30:02,859: WARNING: saving_api: You are saving your model as an HDF5 file via `model.save()` or `keras.saving.save_model(model)`. This file format is considered legacy. We recommend using instead the native Keras format, e.g. `model.save('my_model.keras')` or `keras.saving.save_model(model, 'my_model.keras')`. ]
[2025-05-12 00:30:02,988: INFO: main: >>>>>> stage Prepare base model completed <<<<<<

x==========x]
[2025-05-12 00:30:02,988: INFO: main: *******************]
[2025-05-12 00:30:02,988: INFO: main: >>>>>> stage Training started <<<<<<]
[2025-05-12 00:30:02,990: INFO: common: yaml file: config/config.yaml loaded successfully]
[2025-05-12 00:30:02,991: INFO: common: yaml file: params.yaml loaded successfully]
[2025-05-12 00:30:02,991: INFO: common: created directory at: artifacts]
[2025-05-12 00:30:02,991: INFO: common: created directory at: artifacts/training]
[2025-05-12 00:30:03,180: WARNING: saving_utils: Compiled the loaded model, but the compiled metrics have yet to be built. `model.compile_metrics` will be empty until you train or evaluate the model.]
[2025-05-12 00:30:09,976: ERROR: main: Unknown variable: <Variable path=dense/kernel, shape=(25088, 2), dtype=float32, value=[[-0.00446287  0.00232961]
 [-0.01095678 -0.00593368]
 [ 0.00239723 -0.00332491]
 ...
 [-0.0136307  -0.01512925]
 [-0.01450734 -0.00369766]
 [ 0.00811486 -0.0064235 ]]>. This optimizer can only be called for the variables it was originally built with. When working with a new set of variables, you should recreate a new optimizer instance.]
Traceback (most recent call last):
  File "/media/liganium/Data/Complete End to End Deep Learning Project With MLFLOW,DVC And Deployment/Kidney-Disease-MLOps-Project/main.py", line 42, in <module>
    model_trainer.main()
  File "/media/liganium/Data/Complete End to End Deep Learning Project With MLFLOW,DVC And Deployment/Kidney-Disease-MLOps-Project/src/cnnClassifier/pipeline/stage_03_model_training.py", line 21, in main
    training.train()
  File "/media/liganium/Data/Complete End to End Deep Learning Project With MLFLOW,DVC And Deployment/Kidney-Disease-MLOps-Project/src/cnnClassifier/components/model_training.py", line 85, in train
    self.model.fit(
  File "/media/liganium/Data/Complete End to End Deep Learning Project With MLFLOW,DVC And Deployment/Kidney-Disease-MLOps-Project/kidney_env/lib/python3.12/site-packages/keras/src/utils/traceback_utils.py", line 122, in error_handler
    raise e.with_traceback(filtered_tb) from None
  File "/media/liganium/Data/Complete End to End Deep Learning Project With MLFLOW,DVC And Deployment/Kidney-Disease-MLOps-Project/kidney_env/lib/python3.12/site-packages/keras/src/optimizers/base_optimizer.py", line 329, in _check_variables_are_known
    raise ValueError(
ValueError: Unknown variable: <Variable path=dense/kernel, shape=(25088, 2), dtype=float32, value=[[-0.00446287  0.00232961]
 [-0.01095678 -0.00593368]
 [ 0.00239723 -0.00332491]
 ...
 [-0.0136307  -0.01512925]
 [-0.01450734 -0.00369766]
 [ 0.00811486 -0.0064235 ]]>. This optimizer can only be called for the variables it was originally built with. When working with a new set of variables, you should recreate a new optimizer instance.
[2025-05-12 00:34:54,374: INFO: main: *******************]
[2025-05-12 00:34:54,374: INFO: main: >>>>>> stage Prepare base model started <<<<<<]
[2025-05-12 00:34:54,376: INFO: common: yaml file: config/config.yaml loaded successfully]
[2025-05-12 00:34:54,377: INFO: common: yaml file: params.yaml loaded successfully]
[2025-05-12 00:34:54,377: INFO: common: created directory at: artifacts]
[2025-05-12 00:34:54,377: INFO: common: created directory at: artifacts/prepare_base_model]
[2025-05-12 00:34:56,372: WARNING: saving_api: You are saving your model as an HDF5 file via `model.save()` or `keras.saving.save_model(model)`. This file format is considered legacy. We recommend using instead the native Keras format, e.g. `model.save('my_model.keras')` or `keras.saving.save_model(model, 'my_model.keras')`. ]
[2025-05-12 00:34:56,518: WARNING: saving_api: You are saving your model as an HDF5 file via `model.save()` or `keras.saving.save_model(model)`. This file format is considered legacy. We recommend using instead the native Keras format, e.g. `model.save('my_model.keras')` or `keras.saving.save_model(model, 'my_model.keras')`. ]
[2025-05-12 00:34:56,632: INFO: main: >>>>>> stage Prepare base model completed <<<<<<

x==========x]
[2025-05-12 00:34:56,633: INFO: main: *******************]
[2025-05-12 00:34:56,633: INFO: main: >>>>>> stage Training started <<<<<<]
[2025-05-12 00:34:56,634: INFO: common: yaml file: config/config.yaml loaded successfully]
[2025-05-12 00:34:56,635: INFO: common: yaml file: params.yaml loaded successfully]
[2025-05-12 00:34:56,636: INFO: common: created directory at: artifacts]
[2025-05-12 00:34:56,636: INFO: common: created directory at: artifacts/training]
[2025-05-12 00:34:56,829: WARNING: saving_utils: Compiled the loaded model, but the compiled metrics have yet to be built. `model.compile_metrics` will be empty until you train or evaluate the model.]
[2025-05-12 00:34:56,833: ERROR: main: 'TrainingConfig' object has no attribute 'params_learning_rate']
Traceback (most recent call last):
  File "/media/liganium/Data/Complete End to End Deep Learning Project With MLFLOW,DVC And Deployment/Kidney-Disease-MLOps-Project/main.py", line 42, in <module>
    model_trainer.main()
  File "/media/liganium/Data/Complete End to End Deep Learning Project With MLFLOW,DVC And Deployment/Kidney-Disease-MLOps-Project/src/cnnClassifier/pipeline/stage_03_model_training.py", line 19, in main
    training.get_base_model()
  File "/media/liganium/Data/Complete End to End Deep Learning Project With MLFLOW,DVC And Deployment/Kidney-Disease-MLOps-Project/src/cnnClassifier/components/model_training.py", line 29, in get_base_model
    optimizer=tf.keras.optimizers.Adam(learning_rate=self.config.params_learning_rate),
                                                     ^^^^^^^^^^^^^^^^^^^^^^^^^^^^^^^^
AttributeError: 'TrainingConfig' object has no attribute 'params_learning_rate'
[2025-05-12 00:46:51,304: INFO: main: *******************]
[2025-05-12 00:46:51,304: INFO: main: >>>>>> stage Prepare base model started <<<<<<]
[2025-05-12 00:46:51,305: INFO: common: yaml file: config/config.yaml loaded successfully]
[2025-05-12 00:46:51,306: INFO: common: yaml file: params.yaml loaded successfully]
[2025-05-12 00:46:51,307: INFO: common: created directory at: artifacts]
[2025-05-12 00:46:51,307: INFO: common: created directory at: artifacts/prepare_base_model]
[2025-05-12 00:46:53,323: WARNING: saving_api: You are saving your model as an HDF5 file via `model.save()` or `keras.saving.save_model(model)`. This file format is considered legacy. We recommend using instead the native Keras format, e.g. `model.save('my_model.keras')` or `keras.saving.save_model(model, 'my_model.keras')`. ]
[2025-05-12 00:46:53,481: WARNING: saving_api: You are saving your model as an HDF5 file via `model.save()` or `keras.saving.save_model(model)`. This file format is considered legacy. We recommend using instead the native Keras format, e.g. `model.save('my_model.keras')` or `keras.saving.save_model(model, 'my_model.keras')`. ]
[2025-05-12 00:46:53,600: INFO: main: >>>>>> stage Prepare base model completed <<<<<<

x==========x]
[2025-05-12 00:46:53,600: INFO: main: *******************]
[2025-05-12 00:46:53,600: INFO: main: >>>>>> stage Training started <<<<<<]
[2025-05-12 00:46:53,602: INFO: common: yaml file: config/config.yaml loaded successfully]
[2025-05-12 00:46:53,603: INFO: common: yaml file: params.yaml loaded successfully]
[2025-05-12 00:46:53,603: INFO: common: created directory at: artifacts]
[2025-05-12 00:46:53,603: INFO: common: created directory at: artifacts/training]
[2025-05-12 00:46:53,776: WARNING: saving_utils: Compiled the loaded model, but the compiled metrics have yet to be built. `model.compile_metrics` will be empty until you train or evaluate the model.]
[2025-05-12 00:47:00,542: ERROR: main: Unknown variable: <Variable path=dense/kernel, shape=(25088, 2), dtype=float32, value=[[ 0.00708236  0.00137763]
 [ 0.0031905  -0.00819614]
 [-0.01076882  0.00657441]
 ...
 [ 0.01362108 -0.00162252]
 [ 0.01071635  0.00681586]
 [ 0.01012684 -0.00097629]]>. This optimizer can only be called for the variables it was originally built with. When working with a new set of variables, you should recreate a new optimizer instance.]
Traceback (most recent call last):
  File "/media/liganium/Data/Complete End to End Deep Learning Project With MLFLOW,DVC And Deployment/Kidney-Disease-MLOps-Project/main.py", line 42, in <module>
    model_trainer.main()
  File "/media/liganium/Data/Complete End to End Deep Learning Project With MLFLOW,DVC And Deployment/Kidney-Disease-MLOps-Project/src/cnnClassifier/pipeline/stage_03_model_training.py", line 21, in main
    training.train()
  File "/media/liganium/Data/Complete End to End Deep Learning Project With MLFLOW,DVC And Deployment/Kidney-Disease-MLOps-Project/src/cnnClassifier/components/model_training.py", line 85, in train
    self.model.fit(
  File "/media/liganium/Data/Complete End to End Deep Learning Project With MLFLOW,DVC And Deployment/Kidney-Disease-MLOps-Project/kidney_env/lib/python3.12/site-packages/keras/src/utils/traceback_utils.py", line 122, in error_handler
    raise e.with_traceback(filtered_tb) from None
  File "/media/liganium/Data/Complete End to End Deep Learning Project With MLFLOW,DVC And Deployment/Kidney-Disease-MLOps-Project/kidney_env/lib/python3.12/site-packages/keras/src/optimizers/base_optimizer.py", line 329, in _check_variables_are_known
    raise ValueError(
ValueError: Unknown variable: <Variable path=dense/kernel, shape=(25088, 2), dtype=float32, value=[[ 0.00708236  0.00137763]
 [ 0.0031905  -0.00819614]
 [-0.01076882  0.00657441]
 ...
 [ 0.01362108 -0.00162252]
 [ 0.01071635  0.00681586]
 [ 0.01012684 -0.00097629]]>. This optimizer can only be called for the variables it was originally built with. When working with a new set of variables, you should recreate a new optimizer instance.
[2025-05-12 00:48:36,283: INFO: main: *******************]
[2025-05-12 00:48:36,283: INFO: main: >>>>>> stage Prepare base model started <<<<<<]
[2025-05-12 00:48:36,285: INFO: common: yaml file: config/config.yaml loaded successfully]
[2025-05-12 00:48:36,286: INFO: common: yaml file: params.yaml loaded successfully]
[2025-05-12 00:48:36,286: INFO: common: created directory at: artifacts]
[2025-05-12 00:48:36,286: INFO: common: created directory at: artifacts/prepare_base_model]
[2025-05-12 00:48:38,333: WARNING: saving_api: You are saving your model as an HDF5 file via `model.save()` or `keras.saving.save_model(model)`. This file format is considered legacy. We recommend using instead the native Keras format, e.g. `model.save('my_model.keras')` or `keras.saving.save_model(model, 'my_model.keras')`. ]
[2025-05-12 00:48:38,498: WARNING: saving_api: You are saving your model as an HDF5 file via `model.save()` or `keras.saving.save_model(model)`. This file format is considered legacy. We recommend using instead the native Keras format, e.g. `model.save('my_model.keras')` or `keras.saving.save_model(model, 'my_model.keras')`. ]
[2025-05-12 00:48:38,625: INFO: main: >>>>>> stage Prepare base model completed <<<<<<

x==========x]
[2025-05-12 00:48:38,626: INFO: main: *******************]
[2025-05-12 00:48:38,626: INFO: main: >>>>>> stage Training started <<<<<<]
[2025-05-12 00:48:38,627: INFO: common: yaml file: config/config.yaml loaded successfully]
[2025-05-12 00:48:38,628: INFO: common: yaml file: params.yaml loaded successfully]
[2025-05-12 00:48:38,629: INFO: common: created directory at: artifacts]
[2025-05-12 00:48:38,629: INFO: common: created directory at: artifacts/training]
[2025-05-12 00:48:38,821: WARNING: saving_utils: Compiled the loaded model, but the compiled metrics have yet to be built. `model.compile_metrics` will be empty until you train or evaluate the model.]
[2025-05-12 00:48:45,315: ERROR: main: Unknown variable: <Variable path=dense/kernel, shape=(25088, 2), dtype=float32, value=[[-0.00103457 -0.00194114]
 [-0.00451444 -0.0057786 ]
 [-0.0054882   0.00424211]
 ...
 [ 0.01536104 -0.01525624]
 [ 0.00979531  0.00270885]
 [-0.00676407  0.00572245]]>. This optimizer can only be called for the variables it was originally built with. When working with a new set of variables, you should recreate a new optimizer instance.]
Traceback (most recent call last):
  File "/media/liganium/Data/Complete End to End Deep Learning Project With MLFLOW,DVC And Deployment/Kidney-Disease-MLOps-Project/main.py", line 42, in <module>
    model_trainer.main()
  File "/media/liganium/Data/Complete End to End Deep Learning Project With MLFLOW,DVC And Deployment/Kidney-Disease-MLOps-Project/src/cnnClassifier/pipeline/stage_03_model_training.py", line 21, in main
    training.train()
  File "/media/liganium/Data/Complete End to End Deep Learning Project With MLFLOW,DVC And Deployment/Kidney-Disease-MLOps-Project/src/cnnClassifier/components/model_training.py", line 85, in train
    self.model.fit(
  File "/media/liganium/Data/Complete End to End Deep Learning Project With MLFLOW,DVC And Deployment/Kidney-Disease-MLOps-Project/kidney_env/lib/python3.12/site-packages/keras/src/utils/traceback_utils.py", line 122, in error_handler
    raise e.with_traceback(filtered_tb) from None
  File "/media/liganium/Data/Complete End to End Deep Learning Project With MLFLOW,DVC And Deployment/Kidney-Disease-MLOps-Project/kidney_env/lib/python3.12/site-packages/keras/src/optimizers/base_optimizer.py", line 329, in _check_variables_are_known
    raise ValueError(
ValueError: Unknown variable: <Variable path=dense/kernel, shape=(25088, 2), dtype=float32, value=[[-0.00103457 -0.00194114]
 [-0.00451444 -0.0057786 ]
 [-0.0054882   0.00424211]
 ...
 [ 0.01536104 -0.01525624]
 [ 0.00979531  0.00270885]
 [-0.00676407  0.00572245]]>. This optimizer can only be called for the variables it was originally built with. When working with a new set of variables, you should recreate a new optimizer instance.
[2025-05-12 09:21:00,118: INFO: main: *******************]
[2025-05-12 09:21:00,118: INFO: main: >>>>>> stage Prepare base model started <<<<<<]
[2025-05-12 09:21:00,119: INFO: common: yaml file: config/config.yaml loaded successfully]
[2025-05-12 09:21:00,120: INFO: common: yaml file: params.yaml loaded successfully]
[2025-05-12 09:21:00,120: INFO: common: created directory at: artifacts]
[2025-05-12 09:21:00,120: INFO: common: created directory at: artifacts/prepare_base_model]
[2025-05-12 09:21:01,885: WARNING: saving_api: You are saving your model as an HDF5 file via `model.save()` or `keras.saving.save_model(model)`. This file format is considered legacy. We recommend using instead the native Keras format, e.g. `model.save('my_model.keras')` or `keras.saving.save_model(model, 'my_model.keras')`. ]
[2025-05-12 09:21:01,992: WARNING: saving_api: You are saving your model as an HDF5 file via `model.save()` or `keras.saving.save_model(model)`. This file format is considered legacy. We recommend using instead the native Keras format, e.g. `model.save('my_model.keras')` or `keras.saving.save_model(model, 'my_model.keras')`. ]
[2025-05-12 09:21:02,087: INFO: main: >>>>>> stage Prepare base model completed <<<<<<

x==========x]
[2025-05-12 09:21:02,087: INFO: main: *******************]
[2025-05-12 09:21:02,087: INFO: main: >>>>>> stage Training started <<<<<<]
[2025-05-12 09:21:02,088: INFO: common: yaml file: config/config.yaml loaded successfully]
[2025-05-12 09:21:02,089: INFO: common: yaml file: params.yaml loaded successfully]
[2025-05-12 09:21:02,089: INFO: common: created directory at: artifacts]
[2025-05-12 09:21:02,089: INFO: common: created directory at: artifacts/training]
[2025-05-12 09:21:02,189: WARNING: saving_utils: Compiled the loaded model, but the compiled metrics have yet to be built. `model.compile_metrics` will be empty until you train or evaluate the model.]
[2025-05-12 09:21:02,279: ERROR: main: 'TrainingConfig' object has no attribute 'params_learning_rate']
Traceback (most recent call last):
  File "/media/liganium/Data/Complete End to End Deep Learning Project With MLFLOW,DVC And Deployment/Kidney-Disease-MLOps-Project/main.py", line 42, in <module>
    model_trainer.main()
  File "/media/liganium/Data/Complete End to End Deep Learning Project With MLFLOW,DVC And Deployment/Kidney-Disease-MLOps-Project/src/cnnClassifier/pipeline/stage_03_model_training.py", line 21, in main
    training.train()
  File "/media/liganium/Data/Complete End to End Deep Learning Project With MLFLOW,DVC And Deployment/Kidney-Disease-MLOps-Project/src/cnnClassifier/components/model_training.py", line 86, in train
    optimizer=tf.keras.optimizers.SGD(learning_rate=self.config.params_learning_rate),
                                                    ^^^^^^^^^^^^^^^^^^^^^^^^^^^^^^^^
AttributeError: 'TrainingConfig' object has no attribute 'params_learning_rate'
[2025-05-12 09:23:46,080: INFO: main: *******************]
[2025-05-12 09:23:46,080: INFO: main: >>>>>> stage Prepare base model started <<<<<<]
[2025-05-12 09:23:46,081: INFO: common: yaml file: config/config.yaml loaded successfully]
[2025-05-12 09:23:46,082: INFO: common: yaml file: params.yaml loaded successfully]
[2025-05-12 09:23:46,082: INFO: common: created directory at: artifacts]
[2025-05-12 09:23:46,082: INFO: common: created directory at: artifacts/prepare_base_model]
[2025-05-12 09:23:47,837: WARNING: saving_api: You are saving your model as an HDF5 file via `model.save()` or `keras.saving.save_model(model)`. This file format is considered legacy. We recommend using instead the native Keras format, e.g. `model.save('my_model.keras')` or `keras.saving.save_model(model, 'my_model.keras')`. ]
[2025-05-12 09:23:47,927: WARNING: saving_api: You are saving your model as an HDF5 file via `model.save()` or `keras.saving.save_model(model)`. This file format is considered legacy. We recommend using instead the native Keras format, e.g. `model.save('my_model.keras')` or `keras.saving.save_model(model, 'my_model.keras')`. ]
[2025-05-12 09:23:47,994: INFO: main: >>>>>> stage Prepare base model completed <<<<<<

x==========x]
[2025-05-12 09:23:47,994: INFO: main: *******************]
[2025-05-12 09:23:47,994: INFO: main: >>>>>> stage Training started <<<<<<]
[2025-05-12 09:23:47,995: INFO: common: yaml file: config/config.yaml loaded successfully]
[2025-05-12 09:23:47,996: INFO: common: yaml file: params.yaml loaded successfully]
[2025-05-12 09:23:47,996: INFO: common: created directory at: artifacts]
[2025-05-12 09:23:47,996: INFO: common: created directory at: artifacts/training]
[2025-05-12 09:23:47,996: ERROR: main: TrainingConfig.__init__() missing 1 required positional argument: 'params_learning_rate']
Traceback (most recent call last):
  File "/media/liganium/Data/Complete End to End Deep Learning Project With MLFLOW,DVC And Deployment/Kidney-Disease-MLOps-Project/main.py", line 42, in <module>
    model_trainer.main()
  File "/media/liganium/Data/Complete End to End Deep Learning Project With MLFLOW,DVC And Deployment/Kidney-Disease-MLOps-Project/src/cnnClassifier/pipeline/stage_03_model_training.py", line 17, in main
    training_config = config.get_training_config()
                      ^^^^^^^^^^^^^^^^^^^^^^^^^^^^
  File "/media/liganium/Data/Complete End to End Deep Learning Project With MLFLOW,DVC And Deployment/Kidney-Disease-MLOps-Project/src/cnnClassifier/config/configuration.py", line 70, in get_training_config
    training_config = TrainingConfig(
                      ^^^^^^^^^^^^^^^
TypeError: TrainingConfig.__init__() missing 1 required positional argument: 'params_learning_rate'
[2025-05-12 09:26:07,090: INFO: main: *******************]
[2025-05-12 09:26:07,090: INFO: main: >>>>>> stage Prepare base model started <<<<<<]
[2025-05-12 09:26:07,091: INFO: common: yaml file: config/config.yaml loaded successfully]
[2025-05-12 09:26:07,091: INFO: common: yaml file: params.yaml loaded successfully]
[2025-05-12 09:26:07,091: INFO: common: created directory at: artifacts]
[2025-05-12 09:26:07,091: INFO: common: created directory at: artifacts/prepare_base_model]
[2025-05-12 09:26:08,831: WARNING: saving_api: You are saving your model as an HDF5 file via `model.save()` or `keras.saving.save_model(model)`. This file format is considered legacy. We recommend using instead the native Keras format, e.g. `model.save('my_model.keras')` or `keras.saving.save_model(model, 'my_model.keras')`. ]
[2025-05-12 09:26:08,923: WARNING: saving_api: You are saving your model as an HDF5 file via `model.save()` or `keras.saving.save_model(model)`. This file format is considered legacy. We recommend using instead the native Keras format, e.g. `model.save('my_model.keras')` or `keras.saving.save_model(model, 'my_model.keras')`. ]
[2025-05-12 09:26:08,990: INFO: main: >>>>>> stage Prepare base model completed <<<<<<

x==========x]
[2025-05-12 09:26:08,990: INFO: main: *******************]
[2025-05-12 09:26:08,990: INFO: main: >>>>>> stage Training started <<<<<<]
[2025-05-12 09:26:08,991: INFO: common: yaml file: config/config.yaml loaded successfully]
[2025-05-12 09:26:08,991: INFO: common: yaml file: params.yaml loaded successfully]
[2025-05-12 09:26:08,991: INFO: common: created directory at: artifacts]
[2025-05-12 09:26:08,991: INFO: common: created directory at: artifacts/training]
[2025-05-12 09:26:09,081: WARNING: saving_utils: Compiled the loaded model, but the compiled metrics have yet to be built. `model.compile_metrics` will be empty until you train or evaluate the model.]
[2025-05-12 09:28:38,736: INFO: main: *******************]
[2025-05-12 09:28:38,736: INFO: main: >>>>>> stage Prepare base model started <<<<<<]
[2025-05-12 09:28:38,737: INFO: common: yaml file: config/config.yaml loaded successfully]
[2025-05-12 09:28:38,738: INFO: common: yaml file: params.yaml loaded successfully]
[2025-05-12 09:28:38,738: INFO: common: created directory at: artifacts]
[2025-05-12 09:28:38,738: INFO: common: created directory at: artifacts/prepare_base_model]
[2025-05-12 09:28:40,580: WARNING: saving_api: You are saving your model as an HDF5 file via `model.save()` or `keras.saving.save_model(model)`. This file format is considered legacy. We recommend using instead the native Keras format, e.g. `model.save('my_model.keras')` or `keras.saving.save_model(model, 'my_model.keras')`. ]
[2025-05-12 09:28:40,665: WARNING: saving_api: You are saving your model as an HDF5 file via `model.save()` or `keras.saving.save_model(model)`. This file format is considered legacy. We recommend using instead the native Keras format, e.g. `model.save('my_model.keras')` or `keras.saving.save_model(model, 'my_model.keras')`. ]
[2025-05-12 09:28:40,728: INFO: main: >>>>>> stage Prepare base model completed <<<<<<

x==========x]
[2025-05-12 09:28:40,728: INFO: main: *******************]
[2025-05-12 09:28:40,728: INFO: main: >>>>>> stage Training started <<<<<<]
[2025-05-12 09:28:40,729: INFO: common: yaml file: config/config.yaml loaded successfully]
[2025-05-12 09:28:40,730: INFO: common: yaml file: params.yaml loaded successfully]
[2025-05-12 09:28:40,730: INFO: common: created directory at: artifacts]
[2025-05-12 09:28:40,730: INFO: common: created directory at: artifacts/training]
[2025-05-12 09:28:40,816: WARNING: saving_utils: Compiled the loaded model, but the compiled metrics have yet to be built. `model.compile_metrics` will be empty until you train or evaluate the model.]
[2025-05-12 09:35:08,284: WARNING: saving_api: You are saving your model as an HDF5 file via `model.save()` or `keras.saving.save_model(model)`. This file format is considered legacy. We recommend using instead the native Keras format, e.g. `model.save('my_model.keras')` or `keras.saving.save_model(model, 'my_model.keras')`. ]
[2025-05-12 09:35:08,354: INFO: main: >>>>>> stage Training completed <<<<<<

x==========x]
[2025-05-12 12:35:25,721: INFO: main: *******************]
[2025-05-12 12:35:25,724: INFO: main: >>>>>> stage Prepare base model started <<<<<<]
[2025-05-12 12:35:25,728: INFO: common: yaml file: config/config.yaml loaded successfully]
[2025-05-12 12:35:25,735: INFO: common: yaml file: params.yaml loaded successfully]
[2025-05-12 12:35:25,737: INFO: common: created directory at: artifacts]
[2025-05-12 12:35:25,738: INFO: common: created directory at: artifacts/prepare_base_model]
[2025-05-12 12:35:27,428: WARNING: saving_api: You are saving your model as an HDF5 file via `model.save()` or `keras.saving.save_model(model)`. This file format is considered legacy. We recommend using instead the native Keras format, e.g. `model.save('my_model.keras')` or `keras.saving.save_model(model, 'my_model.keras')`. ]
[2025-05-12 12:35:27,949: WARNING: saving_api: You are saving your model as an HDF5 file via `model.save()` or `keras.saving.save_model(model)`. This file format is considered legacy. We recommend using instead the native Keras format, e.g. `model.save('my_model.keras')` or `keras.saving.save_model(model, 'my_model.keras')`. ]
[2025-05-12 12:35:28,400: INFO: main: >>>>>> stage Prepare base model completed <<<<<<

x==========x]
[2025-05-12 12:35:28,405: INFO: main: *******************]
[2025-05-12 12:35:28,405: INFO: main: >>>>>> stage Training started <<<<<<]
[2025-05-12 12:35:28,408: INFO: common: yaml file: config/config.yaml loaded successfully]
[2025-05-12 12:35:28,413: INFO: common: yaml file: params.yaml loaded successfully]
[2025-05-12 12:35:28,414: INFO: common: created directory at: artifacts]
[2025-05-12 12:35:28,415: INFO: common: created directory at: artifacts/training]
[2025-05-12 12:35:28,982: WARNING: saving_utils: Compiled the loaded model, but the compiled metrics have yet to be built. `model.compile_metrics` will be empty until you train or evaluate the model.]
[2025-05-12 12:36:53,821: INFO: main: *******************]
[2025-05-12 12:36:53,822: INFO: main: >>>>>> stage Evaluation stage started <<<<<<]
[2025-05-12 12:36:53,824: INFO: common: yaml file: config/config.yaml loaded successfully]
[2025-05-12 12:36:53,828: INFO: common: yaml file: params.yaml loaded successfully]
[2025-05-12 12:36:53,829: INFO: common: created directory at: artifacts]
[2025-05-12 12:36:55,987: WARNING: saving_utils: Compiled the loaded model, but the compiled metrics have yet to be built. `model.compile_metrics` will be empty until you train or evaluate the model.]
[2025-05-12 12:40:07,728: INFO: common: json file saved at: scores.json]
[2025-05-12 12:40:07,730: INFO: common: json file saved at: scores.json]
[2025-05-12 12:40:07,730: INFO: main: >>>>>> stage Evaluation stage completed <<<<<<

x==========x]
[2025-05-12 12:47:53,344: INFO: main: *******************]
[2025-05-12 12:47:53,344: INFO: main: >>>>>> stage Evaluation stage started <<<<<<]
[2025-05-12 12:47:53,346: INFO: common: yaml file: config/config.yaml loaded successfully]
[2025-05-12 12:47:53,348: INFO: common: yaml file: params.yaml loaded successfully]
[2025-05-12 12:47:53,348: INFO: common: created directory at: artifacts]
[2025-05-12 12:47:55,446: WARNING: saving_utils: Compiled the loaded model, but the compiled metrics have yet to be built. `model.compile_metrics` will be empty until you train or evaluate the model.]
[2025-05-12 16:32:54,266: INFO: common: json file saved at: scores.json]
[2025-05-12 16:32:54,267: INFO: common: json file saved at: scores.json]
[2025-05-12 16:32:54,267: INFO: main: >>>>>> stage Evaluation stage completed <<<<<<

x==========x]
[2025-05-13 17:14:17,533: INFO: main: >>>>>> stage Data Ingestion stage started <<<<<<]
[2025-05-13 17:14:17,535: INFO: common: yaml file: config/config.yaml loaded successfully]
[2025-05-13 17:14:17,537: INFO: common: yaml file: params.yaml loaded successfully]
[2025-05-13 17:14:17,537: INFO: common: created directory at: artifacts]
[2025-05-13 17:14:17,537: INFO: common: created directory at: artifacts/data_ingestion]
[2025-05-13 17:14:17,537: INFO: data_ingestion: Downloading data from https://drive.google.com/file/d/17BJwWDAin2sJCpJ7-iZTba3OxNhv7vc-/view?usp=sharing into file artifacts/data_ingestion/data.zip]
[2025-05-13 17:16:33,442: ERROR: main: HTTPSConnectionPool(host='drive.google.com', port=443): Max retries exceeded with url: /uc?/export=download&id=17BJwWDAin2sJCpJ7-iZTba3OxNhv7vc- (Caused by NewConnectionError('<urllib3.connection.HTTPSConnection object at 0x7ed50a2dbad0>: Failed to establish a new connection: [Errno 101] Network is unreachable'))]
Traceback (most recent call last):
  File "/media/liganium/Data/Complete End to End Deep Learning Project With MLFLOW,DVC And Deployment/Kidney-Disease-MLOps-Project/kidney_env/lib/python3.12/site-packages/urllib3/connection.py", line 198, in _new_conn
    sock = connection.create_connection(
           ^^^^^^^^^^^^^^^^^^^^^^^^^^^^^
  File "/media/liganium/Data/Complete End to End Deep Learning Project With MLFLOW,DVC And Deployment/Kidney-Disease-MLOps-Project/kidney_env/lib/python3.12/site-packages/urllib3/util/connection.py", line 85, in create_connection
    raise err
  File "/media/liganium/Data/Complete End to End Deep Learning Project With MLFLOW,DVC And Deployment/Kidney-Disease-MLOps-Project/kidney_env/lib/python3.12/site-packages/urllib3/util/connection.py", line 73, in create_connection
    sock.connect(sa)
OSError: [Errno 101] Network is unreachable

The above exception was the direct cause of the following exception:

Traceback (most recent call last):
  File "/media/liganium/Data/Complete End to End Deep Learning Project With MLFLOW,DVC And Deployment/Kidney-Disease-MLOps-Project/kidney_env/lib/python3.12/site-packages/urllib3/connectionpool.py", line 787, in urlopen
    response = self._make_request(
               ^^^^^^^^^^^^^^^^^^^
  File "/media/liganium/Data/Complete End to End Deep Learning Project With MLFLOW,DVC And Deployment/Kidney-Disease-MLOps-Project/kidney_env/lib/python3.12/site-packages/urllib3/connectionpool.py", line 488, in _make_request
    raise new_e
  File "/media/liganium/Data/Complete End to End Deep Learning Project With MLFLOW,DVC And Deployment/Kidney-Disease-MLOps-Project/kidney_env/lib/python3.12/site-packages/urllib3/connectionpool.py", line 464, in _make_request
    self._validate_conn(conn)
  File "/media/liganium/Data/Complete End to End Deep Learning Project With MLFLOW,DVC And Deployment/Kidney-Disease-MLOps-Project/kidney_env/lib/python3.12/site-packages/urllib3/connectionpool.py", line 1093, in _validate_conn
    conn.connect()
  File "/media/liganium/Data/Complete End to End Deep Learning Project With MLFLOW,DVC And Deployment/Kidney-Disease-MLOps-Project/kidney_env/lib/python3.12/site-packages/urllib3/connection.py", line 704, in connect
    self.sock = sock = self._new_conn()
                       ^^^^^^^^^^^^^^^^
  File "/media/liganium/Data/Complete End to End Deep Learning Project With MLFLOW,DVC And Deployment/Kidney-Disease-MLOps-Project/kidney_env/lib/python3.12/site-packages/urllib3/connection.py", line 213, in _new_conn
    raise NewConnectionError(
urllib3.exceptions.NewConnectionError: <urllib3.connection.HTTPSConnection object at 0x7ed50a2dbad0>: Failed to establish a new connection: [Errno 101] Network is unreachable

The above exception was the direct cause of the following exception:

Traceback (most recent call last):
  File "/media/liganium/Data/Complete End to End Deep Learning Project With MLFLOW,DVC And Deployment/Kidney-Disease-MLOps-Project/kidney_env/lib/python3.12/site-packages/requests/adapters.py", line 667, in send
    resp = conn.urlopen(
           ^^^^^^^^^^^^^
  File "/media/liganium/Data/Complete End to End Deep Learning Project With MLFLOW,DVC And Deployment/Kidney-Disease-MLOps-Project/kidney_env/lib/python3.12/site-packages/urllib3/connectionpool.py", line 841, in urlopen
    retries = retries.increment(
              ^^^^^^^^^^^^^^^^^^
  File "/media/liganium/Data/Complete End to End Deep Learning Project With MLFLOW,DVC And Deployment/Kidney-Disease-MLOps-Project/kidney_env/lib/python3.12/site-packages/urllib3/util/retry.py", line 519, in increment
    raise MaxRetryError(_pool, url, reason) from reason  # type: ignore[arg-type]
    ^^^^^^^^^^^^^^^^^^^^^^^^^^^^^^^^^^^^^^^^^^^^^^^^^^^
urllib3.exceptions.MaxRetryError: HTTPSConnectionPool(host='drive.google.com', port=443): Max retries exceeded with url: /uc?/export=download&id=17BJwWDAin2sJCpJ7-iZTba3OxNhv7vc- (Caused by NewConnectionError('<urllib3.connection.HTTPSConnection object at 0x7ed50a2dbad0>: Failed to establish a new connection: [Errno 101] Network is unreachable'))

During handling of the above exception, another exception occurred:

Traceback (most recent call last):
  File "/media/liganium/Data/Complete End to End Deep Learning Project With MLFLOW,DVC And Deployment/Kidney-Disease-MLOps-Project/main.py", line 14, in <module>
    data_ingestion.main()
  File "/media/liganium/Data/Complete End to End Deep Learning Project With MLFLOW,DVC And Deployment/Kidney-Disease-MLOps-Project/src/cnnClassifier/pipeline/stage_01_data_ingestion.py", line 16, in main
    data_ingestion.download_file()
  File "/media/liganium/Data/Complete End to End Deep Learning Project With MLFLOW,DVC And Deployment/Kidney-Disease-MLOps-Project/src/cnnClassifier/components/data_ingestion.py", line 33, in download_file
    raise e
  File "/media/liganium/Data/Complete End to End Deep Learning Project With MLFLOW,DVC And Deployment/Kidney-Disease-MLOps-Project/src/cnnClassifier/components/data_ingestion.py", line 28, in download_file
    gdown.download(prefix+file_id,zip_download_dir)
  File "/media/liganium/Data/Complete End to End Deep Learning Project With MLFLOW,DVC And Deployment/Kidney-Disease-MLOps-Project/kidney_env/lib/python3.12/site-packages/gdown/download.py", line 202, in download
    res = sess.get(url, stream=True, verify=verify)
          ^^^^^^^^^^^^^^^^^^^^^^^^^^^^^^^^^^^^^^^^^
  File "/media/liganium/Data/Complete End to End Deep Learning Project With MLFLOW,DVC And Deployment/Kidney-Disease-MLOps-Project/kidney_env/lib/python3.12/site-packages/requests/sessions.py", line 602, in get
    return self.request("GET", url, **kwargs)
           ^^^^^^^^^^^^^^^^^^^^^^^^^^^^^^^^^^
  File "/media/liganium/Data/Complete End to End Deep Learning Project With MLFLOW,DVC And Deployment/Kidney-Disease-MLOps-Project/kidney_env/lib/python3.12/site-packages/requests/sessions.py", line 589, in request
    resp = self.send(prep, **send_kwargs)
           ^^^^^^^^^^^^^^^^^^^^^^^^^^^^^^
  File "/media/liganium/Data/Complete End to End Deep Learning Project With MLFLOW,DVC And Deployment/Kidney-Disease-MLOps-Project/kidney_env/lib/python3.12/site-packages/requests/sessions.py", line 703, in send
    r = adapter.send(request, **kwargs)
        ^^^^^^^^^^^^^^^^^^^^^^^^^^^^^^^
  File "/media/liganium/Data/Complete End to End Deep Learning Project With MLFLOW,DVC And Deployment/Kidney-Disease-MLOps-Project/kidney_env/lib/python3.12/site-packages/requests/adapters.py", line 700, in send
    raise ConnectionError(e, request=request)
requests.exceptions.ConnectionError: HTTPSConnectionPool(host='drive.google.com', port=443): Max retries exceeded with url: /uc?/export=download&id=17BJwWDAin2sJCpJ7-iZTba3OxNhv7vc- (Caused by NewConnectionError('<urllib3.connection.HTTPSConnection object at 0x7ed50a2dbad0>: Failed to establish a new connection: [Errno 101] Network is unreachable'))
[2025-05-13 17:17:02,604: INFO: main: >>>>>> stage Data Ingestion stage started <<<<<<]
[2025-05-13 17:17:02,606: INFO: common: yaml file: config/config.yaml loaded successfully]
[2025-05-13 17:17:02,607: INFO: common: yaml file: params.yaml loaded successfully]
[2025-05-13 17:17:02,607: INFO: common: created directory at: artifacts]
[2025-05-13 17:17:02,607: INFO: common: created directory at: artifacts/data_ingestion]
[2025-05-13 17:17:02,607: INFO: data_ingestion: Downloading data from https://drive.google.com/file/d/17BJwWDAin2sJCpJ7-iZTba3OxNhv7vc-/view?usp=sharing into file artifacts/data_ingestion/data.zip]
[2025-05-13 17:19:17,282: ERROR: main: HTTPSConnectionPool(host='drive.google.com', port=443): Max retries exceeded with url: /uc?/export=download&id=17BJwWDAin2sJCpJ7-iZTba3OxNhv7vc- (Caused by NewConnectionError('<urllib3.connection.HTTPSConnection object at 0x79ede7d31190>: Failed to establish a new connection: [Errno 101] Network is unreachable'))]
Traceback (most recent call last):
  File "/media/liganium/Data/Complete End to End Deep Learning Project With MLFLOW,DVC And Deployment/Kidney-Disease-MLOps-Project/kidney_env/lib/python3.12/site-packages/urllib3/connection.py", line 198, in _new_conn
    sock = connection.create_connection(
           ^^^^^^^^^^^^^^^^^^^^^^^^^^^^^
  File "/media/liganium/Data/Complete End to End Deep Learning Project With MLFLOW,DVC And Deployment/Kidney-Disease-MLOps-Project/kidney_env/lib/python3.12/site-packages/urllib3/util/connection.py", line 85, in create_connection
    raise err
  File "/media/liganium/Data/Complete End to End Deep Learning Project With MLFLOW,DVC And Deployment/Kidney-Disease-MLOps-Project/kidney_env/lib/python3.12/site-packages/urllib3/util/connection.py", line 73, in create_connection
    sock.connect(sa)
OSError: [Errno 101] Network is unreachable

The above exception was the direct cause of the following exception:

Traceback (most recent call last):
  File "/media/liganium/Data/Complete End to End Deep Learning Project With MLFLOW,DVC And Deployment/Kidney-Disease-MLOps-Project/kidney_env/lib/python3.12/site-packages/urllib3/connectionpool.py", line 787, in urlopen
    response = self._make_request(
               ^^^^^^^^^^^^^^^^^^^
  File "/media/liganium/Data/Complete End to End Deep Learning Project With MLFLOW,DVC And Deployment/Kidney-Disease-MLOps-Project/kidney_env/lib/python3.12/site-packages/urllib3/connectionpool.py", line 488, in _make_request
    raise new_e
  File "/media/liganium/Data/Complete End to End Deep Learning Project With MLFLOW,DVC And Deployment/Kidney-Disease-MLOps-Project/kidney_env/lib/python3.12/site-packages/urllib3/connectionpool.py", line 464, in _make_request
    self._validate_conn(conn)
  File "/media/liganium/Data/Complete End to End Deep Learning Project With MLFLOW,DVC And Deployment/Kidney-Disease-MLOps-Project/kidney_env/lib/python3.12/site-packages/urllib3/connectionpool.py", line 1093, in _validate_conn
    conn.connect()
  File "/media/liganium/Data/Complete End to End Deep Learning Project With MLFLOW,DVC And Deployment/Kidney-Disease-MLOps-Project/kidney_env/lib/python3.12/site-packages/urllib3/connection.py", line 704, in connect
    self.sock = sock = self._new_conn()
                       ^^^^^^^^^^^^^^^^
  File "/media/liganium/Data/Complete End to End Deep Learning Project With MLFLOW,DVC And Deployment/Kidney-Disease-MLOps-Project/kidney_env/lib/python3.12/site-packages/urllib3/connection.py", line 213, in _new_conn
    raise NewConnectionError(
urllib3.exceptions.NewConnectionError: <urllib3.connection.HTTPSConnection object at 0x79ede7d31190>: Failed to establish a new connection: [Errno 101] Network is unreachable

The above exception was the direct cause of the following exception:

Traceback (most recent call last):
  File "/media/liganium/Data/Complete End to End Deep Learning Project With MLFLOW,DVC And Deployment/Kidney-Disease-MLOps-Project/kidney_env/lib/python3.12/site-packages/requests/adapters.py", line 667, in send
    resp = conn.urlopen(
           ^^^^^^^^^^^^^
  File "/media/liganium/Data/Complete End to End Deep Learning Project With MLFLOW,DVC And Deployment/Kidney-Disease-MLOps-Project/kidney_env/lib/python3.12/site-packages/urllib3/connectionpool.py", line 841, in urlopen
    retries = retries.increment(
              ^^^^^^^^^^^^^^^^^^
  File "/media/liganium/Data/Complete End to End Deep Learning Project With MLFLOW,DVC And Deployment/Kidney-Disease-MLOps-Project/kidney_env/lib/python3.12/site-packages/urllib3/util/retry.py", line 519, in increment
    raise MaxRetryError(_pool, url, reason) from reason  # type: ignore[arg-type]
    ^^^^^^^^^^^^^^^^^^^^^^^^^^^^^^^^^^^^^^^^^^^^^^^^^^^
urllib3.exceptions.MaxRetryError: HTTPSConnectionPool(host='drive.google.com', port=443): Max retries exceeded with url: /uc?/export=download&id=17BJwWDAin2sJCpJ7-iZTba3OxNhv7vc- (Caused by NewConnectionError('<urllib3.connection.HTTPSConnection object at 0x79ede7d31190>: Failed to establish a new connection: [Errno 101] Network is unreachable'))

During handling of the above exception, another exception occurred:

Traceback (most recent call last):
  File "/media/liganium/Data/Complete End to End Deep Learning Project With MLFLOW,DVC And Deployment/Kidney-Disease-MLOps-Project/main.py", line 14, in <module>
    data_ingestion.main()
  File "/media/liganium/Data/Complete End to End Deep Learning Project With MLFLOW,DVC And Deployment/Kidney-Disease-MLOps-Project/src/cnnClassifier/pipeline/stage_01_data_ingestion.py", line 16, in main
    data_ingestion.download_file()
  File "/media/liganium/Data/Complete End to End Deep Learning Project With MLFLOW,DVC And Deployment/Kidney-Disease-MLOps-Project/src/cnnClassifier/components/data_ingestion.py", line 33, in download_file
    raise e
  File "/media/liganium/Data/Complete End to End Deep Learning Project With MLFLOW,DVC And Deployment/Kidney-Disease-MLOps-Project/src/cnnClassifier/components/data_ingestion.py", line 28, in download_file
    gdown.download(prefix+file_id,zip_download_dir)
  File "/media/liganium/Data/Complete End to End Deep Learning Project With MLFLOW,DVC And Deployment/Kidney-Disease-MLOps-Project/kidney_env/lib/python3.12/site-packages/gdown/download.py", line 202, in download
    res = sess.get(url, stream=True, verify=verify)
          ^^^^^^^^^^^^^^^^^^^^^^^^^^^^^^^^^^^^^^^^^
  File "/media/liganium/Data/Complete End to End Deep Learning Project With MLFLOW,DVC And Deployment/Kidney-Disease-MLOps-Project/kidney_env/lib/python3.12/site-packages/requests/sessions.py", line 602, in get
    return self.request("GET", url, **kwargs)
           ^^^^^^^^^^^^^^^^^^^^^^^^^^^^^^^^^^
  File "/media/liganium/Data/Complete End to End Deep Learning Project With MLFLOW,DVC And Deployment/Kidney-Disease-MLOps-Project/kidney_env/lib/python3.12/site-packages/requests/sessions.py", line 589, in request
    resp = self.send(prep, **send_kwargs)
           ^^^^^^^^^^^^^^^^^^^^^^^^^^^^^^
  File "/media/liganium/Data/Complete End to End Deep Learning Project With MLFLOW,DVC And Deployment/Kidney-Disease-MLOps-Project/kidney_env/lib/python3.12/site-packages/requests/sessions.py", line 703, in send
    r = adapter.send(request, **kwargs)
        ^^^^^^^^^^^^^^^^^^^^^^^^^^^^^^^
  File "/media/liganium/Data/Complete End to End Deep Learning Project With MLFLOW,DVC And Deployment/Kidney-Disease-MLOps-Project/kidney_env/lib/python3.12/site-packages/requests/adapters.py", line 700, in send
    raise ConnectionError(e, request=request)
requests.exceptions.ConnectionError: HTTPSConnectionPool(host='drive.google.com', port=443): Max retries exceeded with url: /uc?/export=download&id=17BJwWDAin2sJCpJ7-iZTba3OxNhv7vc- (Caused by NewConnectionError('<urllib3.connection.HTTPSConnection object at 0x79ede7d31190>: Failed to establish a new connection: [Errno 101] Network is unreachable'))
[2025-05-13 17:19:45,575: INFO: main: >>>>>> stage Data Ingestion stage started <<<<<<]
[2025-05-13 17:19:45,576: INFO: common: yaml file: config/config.yaml loaded successfully]
[2025-05-13 17:19:45,577: INFO: common: yaml file: params.yaml loaded successfully]
[2025-05-13 17:19:45,577: INFO: common: created directory at: artifacts]
[2025-05-13 17:19:45,577: INFO: common: created directory at: artifacts/data_ingestion]
[2025-05-13 17:19:45,577: INFO: data_ingestion: Downloading data from https://drive.google.com/file/d/17BJwWDAin2sJCpJ7-iZTba3OxNhv7vc-/view?usp=sharing into file artifacts/data_ingestion/data.zip]
[2025-05-13 17:24:41,171: INFO: data_ingestion: Downloaded data from https://drive.google.com/file/d/17BJwWDAin2sJCpJ7-iZTba3OxNhv7vc-/view?usp=sharing into file artifacts/data_ingestion/data.zip]
[2025-05-13 17:24:49,225: INFO: main: >>>>>> stage Data Ingestion stage completed <<<<<<

x==========x]
[2025-05-13 17:24:49,225: INFO: main: *******************]
[2025-05-13 17:24:49,225: INFO: main: >>>>>> stage Prepare base model started <<<<<<]
[2025-05-13 17:24:49,226: INFO: common: yaml file: config/config.yaml loaded successfully]
[2025-05-13 17:24:49,227: INFO: common: yaml file: params.yaml loaded successfully]
[2025-05-13 17:24:49,228: INFO: common: created directory at: artifacts]
[2025-05-13 17:24:49,228: INFO: common: created directory at: artifacts/prepare_base_model]
[2025-05-13 17:24:51,447: WARNING: saving_api: You are saving your model as an HDF5 file via `model.save()` or `keras.saving.save_model(model)`. This file format is considered legacy. We recommend using instead the native Keras format, e.g. `model.save('my_model.keras')` or `keras.saving.save_model(model, 'my_model.keras')`. ]
[2025-05-13 17:24:51,670: WARNING: saving_api: You are saving your model as an HDF5 file via `model.save()` or `keras.saving.save_model(model)`. This file format is considered legacy. We recommend using instead the native Keras format, e.g. `model.save('my_model.keras')` or `keras.saving.save_model(model, 'my_model.keras')`. ]
[2025-05-13 17:24:51,805: INFO: main: >>>>>> stage Prepare base model completed <<<<<<

x==========x]
[2025-05-13 17:24:51,805: INFO: main: *******************]
[2025-05-13 17:24:51,805: INFO: main: >>>>>> stage Training started <<<<<<]
[2025-05-13 17:24:51,807: INFO: common: yaml file: config/config.yaml loaded successfully]
[2025-05-13 17:24:51,808: INFO: common: yaml file: params.yaml loaded successfully]
[2025-05-13 17:24:51,808: INFO: common: created directory at: artifacts]
[2025-05-13 17:24:51,808: INFO: common: created directory at: artifacts/training]
[2025-05-13 17:24:51,995: WARNING: saving_utils: Compiled the loaded model, but the compiled metrics have yet to be built. `model.compile_metrics` will be empty until you train or evaluate the model.]
[2025-05-13 17:34:42,593: WARNING: saving_api: You are saving your model as an HDF5 file via `model.save()` or `keras.saving.save_model(model)`. This file format is considered legacy. We recommend using instead the native Keras format, e.g. `model.save('my_model.keras')` or `keras.saving.save_model(model, 'my_model.keras')`. ]
[2025-05-13 17:34:42,675: INFO: main: >>>>>> stage Training completed <<<<<<

x==========x]
[2025-05-13 17:34:42,675: INFO: main: *******************]
[2025-05-13 17:34:42,675: INFO: main: >>>>>> stage Evaluation stage started <<<<<<]
[2025-05-13 17:34:42,676: INFO: common: yaml file: config/config.yaml loaded successfully]
[2025-05-13 17:34:42,677: INFO: common: yaml file: params.yaml loaded successfully]
[2025-05-13 17:34:42,678: INFO: common: created directory at: artifacts]
[2025-05-13 17:34:42,838: WARNING: saving_utils: Compiled the loaded model, but the compiled metrics have yet to be built. `model.compile_metrics` will be empty until you train or evaluate the model.]
[2025-05-13 17:37:39,182: INFO: common: json file saved at: scores.json]
[2025-05-13 17:37:39,182: INFO: common: json file saved at: scores.json]
[2025-05-13 17:37:39,182: INFO: main: >>>>>> stage Evaluation stage completed <<<<<<

x==========x]
[2025-05-13 17:41:53,115: INFO: main: *******************]
[2025-05-13 17:41:53,115: INFO: main: >>>>>> stage Training started <<<<<<]
[2025-05-13 17:41:53,117: INFO: common: yaml file: config/config.yaml loaded successfully]
[2025-05-13 17:41:53,118: INFO: common: yaml file: params.yaml loaded successfully]
[2025-05-13 17:41:53,118: INFO: common: created directory at: artifacts]
[2025-05-13 17:41:53,118: INFO: common: created directory at: artifacts/training]
[2025-05-13 17:41:55,010: WARNING: saving_utils: Compiled the loaded model, but the compiled metrics have yet to be built. `model.compile_metrics` will be empty until you train or evaluate the model.]
[2025-05-13 17:53:40,250: WARNING: saving_api: You are saving your model as an HDF5 file via `model.save()` or `keras.saving.save_model(model)`. This file format is considered legacy. We recommend using instead the native Keras format, e.g. `model.save('my_model.keras')` or `keras.saving.save_model(model, 'my_model.keras')`. ]
[2025-05-13 17:53:40,358: INFO: main: >>>>>> stage Training completed <<<<<<

x==========x]
[2025-05-13 17:53:40,358: INFO: main: *******************]
[2025-05-13 17:53:40,358: INFO: main: >>>>>> stage Evaluation stage started <<<<<<]
[2025-05-13 17:53:40,359: INFO: common: yaml file: config/config.yaml loaded successfully]
[2025-05-13 17:53:40,360: INFO: common: yaml file: params.yaml loaded successfully]
[2025-05-13 17:53:40,360: INFO: common: created directory at: artifacts]
[2025-05-13 17:53:40,519: WARNING: saving_utils: Compiled the loaded model, but the compiled metrics have yet to be built. `model.compile_metrics` will be empty until you train or evaluate the model.]
[2025-05-13 17:56:35,832: INFO: common: json file saved at: scores.json]
[2025-05-13 17:56:35,832: INFO: common: json file saved at: scores.json]
[2025-05-13 17:56:53,649: INFO: main: >>>>>> stage Evaluation stage completed <<<<<<

x==========x]
[2025-05-13 17:59:14,421: INFO: main: *******************]
[2025-05-13 17:59:14,421: INFO: main: >>>>>> stage Training started <<<<<<]
[2025-05-13 17:59:14,423: INFO: common: yaml file: config/config.yaml loaded successfully]
[2025-05-13 17:59:14,424: INFO: common: yaml file: params.yaml loaded successfully]
[2025-05-13 17:59:14,424: INFO: common: created directory at: artifacts]
[2025-05-13 17:59:14,424: INFO: common: created directory at: artifacts/training]
[2025-05-13 17:59:16,481: WARNING: saving_utils: Compiled the loaded model, but the compiled metrics have yet to be built. `model.compile_metrics` will be empty until you train or evaluate the model.]
[2025-05-13 18:09:28,700: WARNING: saving_api: You are saving your model as an HDF5 file via `model.save()` or `keras.saving.save_model(model)`. This file format is considered legacy. We recommend using instead the native Keras format, e.g. `model.save('my_model.keras')` or `keras.saving.save_model(model, 'my_model.keras')`. ]
[2025-05-13 18:09:28,830: INFO: main: >>>>>> stage Training completed <<<<<<

x==========x]
[2025-05-13 18:09:28,831: INFO: main: *******************]
[2025-05-13 18:09:28,831: INFO: main: >>>>>> stage Evaluation stage started <<<<<<]
[2025-05-13 18:09:28,832: INFO: common: yaml file: config/config.yaml loaded successfully]
[2025-05-13 18:09:28,833: INFO: common: yaml file: params.yaml loaded successfully]
[2025-05-13 18:09:28,833: INFO: common: created directory at: artifacts]
[2025-05-13 18:09:29,004: WARNING: saving_utils: Compiled the loaded model, but the compiled metrics have yet to be built. `model.compile_metrics` will be empty until you train or evaluate the model.]
[2025-05-13 18:12:32,421: INFO: common: json file saved at: scores.json]
[2025-05-13 18:12:32,421: INFO: common: json file saved at: scores.json]
[2025-05-13 18:12:50,596: INFO: main: >>>>>> stage Evaluation stage completed <<<<<<

x==========x]
[2025-05-13 22:33:43,742: INFO: stage_01_data_ingestion: >>>>>> stage Data Ingestion stage started <<<<<<]
[2025-05-13 22:33:43,744: INFO: common: yaml file: config/config.yaml loaded successfully]
[2025-05-13 22:33:43,745: INFO: common: yaml file: params.yaml loaded successfully]
[2025-05-13 22:33:43,745: INFO: common: created directory at: artifacts]
[2025-05-13 22:33:43,745: INFO: common: created directory at: artifacts/data_ingestion]
[2025-05-13 22:33:43,746: INFO: data_ingestion: Downloading data from https://drive.google.com/file/d/17BJwWDAin2sJCpJ7-iZTba3OxNhv7vc-/view?usp=sharing into file artifacts/data_ingestion/data.zip]
[2025-05-13 22:39:27,149: INFO: stage_02_prepare_base_model: *******************]
[2025-05-13 22:39:27,150: INFO: stage_02_prepare_base_model: >>>>>> stage Prepare base model started <<<<<<]
[2025-05-13 22:39:27,152: INFO: common: yaml file: config/config.yaml loaded successfully]
[2025-05-13 22:39:27,154: INFO: common: yaml file: params.yaml loaded successfully]
[2025-05-13 22:39:27,155: INFO: common: created directory at: artifacts]
[2025-05-13 22:39:27,155: INFO: common: created directory at: artifacts/prepare_base_model]
[2025-05-13 22:39:48,062: WARNING: saving_api: You are saving your model as an HDF5 file via `model.save()` or `keras.saving.save_model(model)`. This file format is considered legacy. We recommend using instead the native Keras format, e.g. `model.save('my_model.keras')` or `keras.saving.save_model(model, 'my_model.keras')`. ]
[2025-05-13 22:43:30,432: INFO: stage_02_prepare_base_model: *******************]
[2025-05-13 22:43:30,432: INFO: stage_02_prepare_base_model: >>>>>> stage Prepare base model started <<<<<<]
[2025-05-13 22:43:30,434: INFO: common: yaml file: config/config.yaml loaded successfully]
[2025-05-13 22:43:30,436: INFO: common: yaml file: params.yaml loaded successfully]
[2025-05-13 22:43:30,436: INFO: common: created directory at: artifacts]
[2025-05-13 22:43:30,437: INFO: common: created directory at: artifacts/prepare_base_model]
[2025-05-13 22:43:32,559: WARNING: saving_api: You are saving your model as an HDF5 file via `model.save()` or `keras.saving.save_model(model)`. This file format is considered legacy. We recommend using instead the native Keras format, e.g. `model.save('my_model.keras')` or `keras.saving.save_model(model, 'my_model.keras')`. ]
[2025-05-13 22:43:32,718: WARNING: saving_api: You are saving your model as an HDF5 file via `model.save()` or `keras.saving.save_model(model)`. This file format is considered legacy. We recommend using instead the native Keras format, e.g. `model.save('my_model.keras')` or `keras.saving.save_model(model, 'my_model.keras')`. ]
[2025-05-13 22:43:32,826: INFO: stage_02_prepare_base_model: >>>>>> stage Prepare base model completed <<<<<<

x==========x]
[2025-05-13 22:43:44,467: INFO: stage_03_model_training: *******************]
[2025-05-13 22:43:44,467: INFO: stage_03_model_training: >>>>>> stage Training started <<<<<<]
[2025-05-13 22:43:44,469: INFO: common: yaml file: config/config.yaml loaded successfully]
[2025-05-13 22:43:44,470: INFO: common: yaml file: params.yaml loaded successfully]
[2025-05-13 22:43:44,470: INFO: common: created directory at: artifacts]
[2025-05-13 22:43:44,470: INFO: common: created directory at: artifacts/training]
[2025-05-13 22:43:44,806: WARNING: saving_utils: Compiled the loaded model, but the compiled metrics have yet to be built. `model.compile_metrics` will be empty until you train or evaluate the model.]
[2025-05-13 22:53:48,286: WARNING: saving_api: You are saving your model as an HDF5 file via `model.save()` or `keras.saving.save_model(model)`. This file format is considered legacy. We recommend using instead the native Keras format, e.g. `model.save('my_model.keras')` or `keras.saving.save_model(model, 'my_model.keras')`. ]
[2025-05-13 22:53:48,395: INFO: stage_03_model_training: >>>>>> stage Training completed <<<<<<

x==========x]
[2025-05-13 22:53:55,440: INFO: stage_04_model_evaluation: *******************]
[2025-05-13 22:53:55,440: INFO: stage_04_model_evaluation: >>>>>> stage Evaluation stage started <<<<<<]
[2025-05-13 22:53:55,442: INFO: common: yaml file: config/config.yaml loaded successfully]
[2025-05-13 22:53:55,443: INFO: common: yaml file: params.yaml loaded successfully]
[2025-05-13 22:53:55,443: INFO: common: created directory at: artifacts]
[2025-05-13 22:53:55,771: WARNING: saving_utils: Compiled the loaded model, but the compiled metrics have yet to be built. `model.compile_metrics` will be empty until you train or evaluate the model.]
[2025-05-13 22:56:51,534: INFO: common: json file saved at: scores.json]
[2025-05-13 22:56:51,534: INFO: common: json file saved at: scores.json]
[2025-05-13 22:56:51,534: INFO: stage_04_model_evaluation: >>>>>> stage Evaluation stage completed <<<<<<

x==========x]
[2025-05-13 23:09:55,446: INFO: stage_01_data_ingestion: >>>>>> stage Data Ingestion stage started <<<<<<]
[2025-05-13 23:09:55,447: INFO: common: yaml file: config/config.yaml loaded successfully]
[2025-05-13 23:09:55,449: INFO: common: yaml file: params.yaml loaded successfully]
[2025-05-13 23:09:55,449: INFO: common: created directory at: artifacts]
[2025-05-13 23:09:55,449: INFO: common: created directory at: artifacts/data_ingestion]
[2025-05-13 23:09:55,449: INFO: data_ingestion: Downloading data from https://drive.google.com/file/d/17BJwWDAin2sJCpJ7-iZTba3OxNhv7vc-/view?usp=sharing into file artifacts/data_ingestion/data.zip]
[2025-05-13 23:10:32,267: INFO: data_ingestion: Downloaded data from https://drive.google.com/file/d/17BJwWDAin2sJCpJ7-iZTba3OxNhv7vc-/view?usp=sharing into file artifacts/data_ingestion/data.zip]
[2025-05-13 23:10:40,370: INFO: stage_01_data_ingestion: >>>>>> stage Data Ingestion stage completed <<<<<<

x==========x]
[2025-05-14 00:21:00,187: INFO: _internal: [31m[1mWARNING: This is a development server. Do not use it in a production deployment. Use a production WSGI server instead.[0m
 * Running on all addresses (0.0.0.0)
 * Running on http://127.0.0.1:8080
 * Running on http://10.155.16.55:8080]
[2025-05-14 00:21:00,187: INFO: _internal: [33mPress CTRL+C to quit[0m]
[2025-05-14 00:21:14,590: INFO: _internal: 127.0.0.1 - - [14/May/2025 00:21:14] "GET / HTTP/1.1" 200 -]
[2025-05-14 00:31:13,808: WARNING: saving_utils: Compiled the loaded model, but the compiled metrics have yet to be built. `model.compile_metrics` will be empty until you train or evaluate the model.]
[2025-05-14 00:31:14,122: INFO: _internal: 127.0.0.1 - - [14/May/2025 00:31:14] "POST /predict HTTP/1.1" 200 -]
